File: Project_codes/Almax_pressure_cell (upright) _Gasket+TAS100+Nujol+Sn+Ruby_background_100_Oe_ZFC-FC_AmbientPressure_3cmfromtop_pressureapplied.dc.raw
[Header]
TITLE,MPMS DC Measurement
BYAPP,MPMS Measurement,2.1,Raw with ABS
FILEOPENTIME, 1607709135.460000 12/11/2020, 6:52:15 PM

INFO, APPNAME, MPMS MultiVu Application, Revision 1.60,  Build 081

INFO, NAME, NiIrRu
INFO, WEIGHT, 1.000
INFO, AREA, 1.000
INFO, LENGTH, 1.000
INFO, SHAPE, 1
INFO, COMMENT,
INFO, SEQUENCE FILE: 29 11 2020 TAS 100 + Sn + Nujol.seq


INFO, BACKGROUND DATA FILE:, None


STARTUPAXIS,X,8,LINEAR,AUTO,0.000000,0.000000
STARTUPAXIS,Y1,10,LINEAR,AUTO,0.000000,0.000000


STARTUPGROUP,Longitudinal
FIELDGROUP,Longitudinal,1,3,4,5,6,8,9,10,11,12,13,14,15,16,17,18,19,20,21,22,23
FIELDGROUP,Transverse,1,3,4,5,6,8,9,24,25,26,27,28,29,30,31,32,33,34,35,36,37

PLOT_APPEARANCE,ALL,HORZ_GRID_ON,VERT_GRID_ON,MARKERS_ONLY

[Data]
Time,Comment,Field (Oe),Start Temperature (K),End Temperature (K),Scan,Rejected,Position (cm),Rot Position (deg),Long Voltage,Long Average Voltage,Long Detrended Voltage,Long Demeaned Voltage,Long Regression Fit,Long Detrended Fit,Long Demeaned Fit,Long Scaled Response,Long Avg. Scaled Response,Long Background Response,Long Response [w/ABS],Long Detrended Resp. [w/ABS],Long Fit [w/ABS],Long Detrended Fit [w/ABS],Trans Voltage,Trans Average Voltage,Trans Detrended Voltage,Trans Demeaned Voltage,Trans Regression Fit,Trans Detrended Fit,Trans Demeaned Fit,Trans Scaled Response,Trans Avg Scaled Response,Trans Background Response,Trans Response [w/ABS],Trans Detrended Resp. [w/ABS],Trans Fit [w/ABS],Trans Detrended Fit [w/ABS],
1607709135.450,,1.000000e+002,1.996480e+000,2.015178e+000,1,0,0.000000e+000,0.000000e+000,1.295796e+000,,,,,,,-3.845344e-007,,,,,,,,,,,,,,,,,,,,,
1607709135.450,,1.000000e+002,1.996480e+000,2.015178e+000,1,0,1.677419e+000,0.000000e+000,1.349203e+000,,,,,,,1.160920e-005,,,,,,,,,,,,,,,,,,,,,
1607709135.450,,1.000000e+002,1.996480e+000,2.015178e+000,1,0,3.354839e+000,0.000000e+000,5.050736e-002,,,,,,,-3.190721e-005,,,,,,,,,,,,,,,,,,,,,
1607709135.450,,1.000000e+002,1.992713e+000,2.005772e+000,2,0,9.032258e-001,0.000000e+000,1.583581e+000,1.451514e+000,-1.717068e-001,-6.304941e-001,1.308874e+000,-3.143476e-001,-7.731349e-001,5.775793e-006,5.819900e-006,,,,,,,,,,,,,,,,,,,,
1607709135.450,,1.000000e+002,1.992713e+000,2.005772e+000,2,0,2.580645e+000,0.000000e+000,1.736324e+000,1.602350e+000,8.311625e-001,-4.796586e-001,1.473383e+000,7.021953e-001,-6.086258e-001,2.194581e-005,2.186257e-005,,,,,,,,,,,,,,,,,,,,
1607712395.514,,1.000000e+002,3.012273e+000,3.011906e+000,1,0,1.290323e-001,0.000000e+000,1.941253e+000,,,,,,,-4.647081e-006,,,,,,,,,,,,,,,,,,,,,
1607712395.514,,1.000000e+002,3.012273e+000,3.011906e+000,1,0,1.806452e+000,0.000000e+000,2.391546e+000,,,,,,,2.074169e-005,,,,,,,,,,,,,,,,,,,,,
1607712395.514,,1.000000e+002,3.012273e+000,3.011906e+000,1,0,3.483871e+000,0.000000e+000,9.059281e-001,,,,,,,-3.334781e-005,,,,,,,,,,,,,,,,,,,,,
1607712395.514,,1.000000e+002,3.011643e+000,3.009702e+000,2,0,1.032258e+000,0.000000e+000,2.017243e+000,1.996490e+000,-1.586009e-001,-5.582504e-001,1.868067e+000,-2.870248e-001,-6.866744e-001,5.741313e-007,5.296752e-007,,,,,,,,,,,,,,,,,,,,
1607712395.514,,1.000000e+002,3.011643e+000,3.009702e+000,2,0,2.709677e+000,0.000000e+000,2.347753e+000,2.329824e+000,8.241628e-001,-2.249172e-001,2.197657e+000,6.919960e-001,-3.570840e-001,2.108958e-005,2.113885e-005,,,,,,,,,,,,,,,,,,,,
1607712720.205,,1.000000e+002,3.998395e+000,4.001191e+000,1,0,2.580645e-001,0.000000e+000,1.329061e+000,,,,,,,-6.836883e-006,,,,,,,,,,,,,,,,,,,,,
1607712720.205,,1.000000e+002,3.998395e+000,4.001191e+000,1,0,1.935484e+000,0.000000e+000,2.004578e+000,,,,,,,2.598688e-005,,,,,,,,,,,,,,,,,,,,,
1607712720.205,,1.000000e+002,3.998395e+000,4.001191e+000,1,0,3.612903e+000,0.000000e+000,3.543145e-001,,,,,,,-3.667355e-005,,,,,,,,,,,,,,,,,,,,,
1607712720.205,,1.000000e+002,3.999960e+000,4.004553e+000,2,0,1.161290e+000,0.000000e+000,1.486381e+000,1.474021e+000,-5.288957e-002,-4.096366e-001,1.353444e+000,-1.734671e-001,-5.302142e-001,1.168999e-006,1.258555e-006,,,,,,,,,,,,,,,,,,,,
1607712720.205,,1.000000e+002,3.999960e+000,4.004553e+000,2,0,2.838710e+000,0.000000e+000,1.713283e+000,1.695354e+000,6.837439e-001,-1.883044e-001,1.561951e+000,5.503412e-001,-3.217071e-001,1.546844e-005,1.538262e-005,,,,,,,,,,,,,,,,,,,,
1607713446.986,,1.000000e+002,5.011558e+000,5.006488e+000,1,0,3.870968e-001,0.000000e+000,2.411383e+000,,,,,,,-9.991098e-006,,,,,,,,,,,,,,,,,,,,,
1607713446.986,,1.000000e+002,5.011558e+000,5.006488e+000,1,0,2.064516e+000,0.000000e+000,3.313649e+000,,,,,,,3.155491e-005,,,,,,,,,,,,,,,,,,,,,
1607713446.986,,1.000000e+002,5.011558e+000,5.006488e+000,1,0,3.741935e+000,0.000000e+000,1.400931e+000,,,,,,,-4.246744e-005,,,,,,,,,,,,,,,,,,,,,
1607713446.986,,1.000000e+002,5.002014e+000,5.004153e+000,2,0,1.290323e+000,0.000000e+000,2.845045e+000,2.828260e+000,1.865779e-001,-1.595535e-001,2.686828e+000,4.514590e-002,-3.009856e-001,8.798102e-006,8.828873e-006,,,,,,,,,,,,,,,,,,,,
1607713446.986,,1.000000e+002,5.002014e+000,5.004153e+000,2,0,2.967742e+000,0.000000e+000,2.647745e+000,2.629511e+000,4.378000e-001,-3.583024e-001,2.498972e+000,3.072609e-001,-4.888415e-001,5.154230e-006,5.149261e-006,,,,,,,,,,,,,,,,,,,,
1607713557.256,,1.000000e+002,6.008817e+000,5.998268e+000,1,0,5.161290e-001,0.000000e+000,1.955901e+000,,,,,,,-1.100879e-005,,,,,,,,,,,,,,,,,,,,,
1607713557.256,,1.000000e+002,6.008817e+000,5.998268e+000,1,0,2.193548e+000,0.000000e+000,2.960708e+000,,,,,,,3.445463e-005,,,,,,,,,,,,,,,,,,,,,
1607713557.256,,1.000000e+002,6.008817e+000,5.998268e+000,1,0,3.870968e+000,0.000000e+000,8.497750e-001,,,,,,,-4.799767e-005,,,,,,,,,,,,,,,,,,,,,
1607713557.256,,1.000000e+002,5.998268e+000,5.995563e+000,2,0,1.419355e+000,0.000000e+000,2.640116e+000,2.621347e+000,4.460292e-001,1.037624e-001,2.477727e+000,3.024092e-001,-3.985763e-002,1.769088e-005,1.774946e-005,,,,,,,,,,,,,,,,,,,,
1607713557.256,,1.000000e+002,5.998268e+000,5.995563e+000,2,0,3.096774e+000,0.000000e+000,1.979858e+000,1.955901e+000,1.850803e-001,-5.616837e-001,1.834590e+000,6.376876e-002,-6.829952e-001,-5.259557e-006,-5.386406e-006,,,,,,,,,,,,,,,,,,,,
1607713669.666,,1.000000e+002,7.005417e+000,7.007121e+000,1,0,6.451613e-001,0.000000e+000,1.833677e+000,,,,,,,-9.993877e-006,,,,,,,,,,,,,,,,,,,,,
1607713669.666,,1.000000e+002,7.005417e+000,7.007121e+000,1,0,2.322581e+000,0.000000e+000,2.815137e+000,,,,,,,3.442660e-005,,,,,,,,,,,,,,,,,,,,,
1607713669.666,,1.000000e+002,7.005417e+000,7.007121e+000,1,0,4.000000e+000,0.000000e+000,6.181430e-001,,,,,,,-5.164338e-005,,,,,,,,,,,,,,,,,,,,,
1607713669.666,,1.000000e+002,7.004779e+000,6.999465e+000,2,0,1.548387e+000,0.000000e+000,2.711986e+000,2.690242e+000,6.943227e-001,3.509634e-001,2.597014e+000,6.010946e-001,2.577353e-001,2.657401e-005,2.653783e-005,,,,,,,,,,,,,,,,,,,,
1607713669.666,,1.000000e+002,7.004779e+000,6.999465e+000,2,0,3.225806e+000,0.000000e+000,1.576257e+000,1.560388e+000,-6.355888e-002,-7.788908e-001,1.446736e+000,-1.772109e-001,-8.925428e-001,-1.592511e-005,-1.572059e-005,,,,,,,,,,,,,,,,,,,,
1607713780.556,,1.000000e+002,8.005653e+000,8.003408e+000,1,0,7.741935e-001,0.000000e+000,2.120852e+000,,,,,,,-6.957009e-006,,,,,,,,,,,,,,,,,,,,,
1607713780.556,,1.000000e+002,8.005653e+000,8.003408e+000,1,0,2.451613e+000,0.000000e+000,2.976577e+000,,,,,,,3.225190e-005,,,,,,,,,,,,,,,,,,,,,
1607713780.556,,1.000000e+002,8.003408e+000,8.001724e+000,2,0,0.000000e+000,0.000000e+000,1.701228e+000,1.691310e+000,-8.377749e-001,-8.377749e-001,2.154345e+000,-3.747404e-001,-3.747404e-001,-2.781024e-005,-2.734549e-005,,,,,,,,,,,,,,,,,,,,
1607713780.556,,1.000000e+002,8.003408e+000,8.001724e+000,2,0,1.677419e+000,0.000000e+000,3.085527e+000,3.048295e+000,8.638268e-001,5.192101e-001,3.056168e+000,8.716996e-001,5.270829e-001,3.291779e-005,3.235182e-005,,,,,,,,,,,,,,,,,,,,
1607713780.556,,1.000000e+002,8.003408e+000,8.001724e+000,2,0,3.354839e+000,0.000000e+000,1.592584e+000,1.568856e+000,-2.709950e-001,-9.602284e-001,1.477740e+000,-3.621118e-001,-1.051345e+000,-2.447845e-005,-2.439937e-005,,,,,,,,,,,,,,,,,,,,
1607713892.706,,1.000000e+002,9.004873e+000,9.004515e+000,1,0,9.032258e-001,0.000000e+000,2.016937e+000,,,,,,,-2.594054e-006,,,,,,,,,,,,,,,,,,,,,
1607713892.706,,1.000000e+002,9.004873e+000,9.004515e+000,1,0,2.580645e+000,0.000000e+000,2.661936e+000,,,,,,,2.761639e-005,,,,,,,,,,,,,,,,,,,,,
1607713892.706,,1.000000e+002,9.001655e+000,8.995583e+000,2,0,1.290323e-001,0.000000e+000,1.542229e+000,1.521324e+000,-7.620507e-001,-7.871957e-001,1.843934e+000,-4.394408e-001,-4.645858e-001,-2.553628e-005,-2.552874e-005,,,,,,,,,,,,,,,,,,,,
1607713892.706,,1.000000e+002,9.001655e+000,8.995583e+000,2,0,1.806452e+000,0.000000e+000,2.903792e+000,2.881514e+000,9.250227e-001,5.729938e-001,3.003687e+000,1.047196e+000,6.951671e-001,3.405023e-005,3.402252e-005,,,,,,,,,,,,,,,,,,,,
1607713892.706,,1.000000e+002,9.001655e+000,8.995583e+000,2,0,3.483871e+000,0.000000e+000,1.234150e+000,1.211795e+000,-4.178120e-001,-1.096725e+000,1.164243e+000,-4.653642e-001,-1.144277e+000,-3.080847e-005,-3.081818e-005,,,,,,,,,,,,,,,,,,,,
1607714005.557,,1.000000e+002,9.999912e+000,9.997698e+000,1,0,1.032258e+000,0.000000e+000,1.544366e+000,,,,,,,1.395601e-006,,,,,,,,,,,,,,,,,,,,,
1607714005.557,,1.000000e+002,9.999912e+000,9.997698e+000,1,0,2.709677e+000,0.000000e+000,1.993896e+000,,,,,,,2.299627e-005,,,,,,,,,,,,,,,,,,,,,
1607714005.557,,1.000000e+002,9.998140e+000,9.999912e+000,2,0,2.580645e-001,0.000000e+000,1.062638e+000,1.042573e+000,-6.416515e-001,-6.893039e-001,1.214442e+000,-4.697827e-001,-5.174351e-001,-2.132337e-005,-2.140211e-005,,,,,,,,,,,,,,,,,,,,
1607714005.557,,1.000000e+002,9.998140e+000,9.999912e+000,2,0,1.935484e+000,0.000000e+000,2.330205e+000,2.310521e+000,9.360375e-001,5.786445e-001,2.492183e+000,1.117699e+000,7.603061e-001,3.380413e-005,3.376976e-005,,,,,,,,,,,,,,,,,,,,
1607714005.557,,1.000000e+002,9.998140e+000,9.999912e+000,2,0,3.612903e+000,0.000000e+000,5.488670e-001,5.306325e-001,-5.341105e-001,-1.201244e+000,5.637094e-001,-5.010336e-001,-1.168167e+000,-3.624025e-005,-3.618641e-005,,,,,,,,,,,,,,,,,,,,
1607714116.557,,1.000000e+002,1.099880e+001,1.098990e+001,1,0,1.161290e+000,0.000000e+000,2.402533e+000,,,,,,,3.703957e-006,,,,,,,,,,,,,,,,,,,,,
1607714116.557,,1.000000e+002,1.099880e+001,1.098990e+001,1,0,2.838710e+000,0.000000e+000,2.688029e+000,,,,,,,1.780105e-005,,,,,,,,,,,,,,,,,,,,,
1607714116.557,,1.000000e+002,1.099015e+001,1.098875e+001,2,0,3.870968e-001,0.000000e+000,1.945983e+000,1.930266e+000,-5.324644e-001,-6.005276e-001,1.982461e+000,-4.802693e-001,-5.483326e-001,-1.760238e-005,-1.751456e-005,,,,,,,,,,,,,,,,,,,,
1607714116.557,,1.000000e+002,1.099015e+001,1.098875e+001,2,0,2.064516e+000,0.000000e+000,3.127794e+000,3.110018e+000,9.422280e-001,5.792239e-001,3.302825e+000,1.135036e+000,7.720315e-001,3.328148e-005,3.329031e-005,,,,,,,,,,,,,,,,,,,,
1607714116.557,,1.000000e+002,1.099015e+001,1.098875e+001,2,0,3.741935e+000,0.000000e+000,1.267262e+000,1.253452e+000,-6.193966e-001,-1.277342e+000,1.365771e+000,-5.070782e-001,-1.165023e+000,-4.073714e-005,-4.055985e-005,,,,,,,,,,,,,,,,,,,,
1607714229.137,,1.000000e+002,1.199323e+001,1.199372e+001,1,0,1.290323e+000,0.000000e+000,1.885557e+000,,,,,,,7.257302e-006,,,,,,,,,,,,,,,,,,,,,
1607714229.137,,1.000000e+002,1.199323e+001,1.199372e+001,1,0,2.967742e+000,0.000000e+000,1.913481e+000,,,,,,,1.038270e-005,,,,,,,,,,,,,,,,,,,,,
1607714229.137,,1.000000e+002,1.199652e+001,1.199486e+001,2,0,5.161290e-001,0.000000e+000,1.387961e+000,1.366140e+000,-4.696882e-001,-5.578545e-001,1.328223e+000,-5.076060e-001,-5.957724e-001,-1.554642e-005,-1.571142e-005,,,,,,,,,,,,,,,,,,,,
1607714229.137,,1.000000e+002,1.199652e+001,1.199486e+001,2,0,2.193548e+000,0.000000e+000,2.564431e+000,2.547036e+000,9.977479e-001,6.230410e-001,2.728559e+000,1.179271e+000,8.045641e-001,3.471968e-005,3.474262e-005,,,,,,,,,,,,,,,,,,,,
1607714229.137,,1.000000e+002,1.199652e+001,1.199486e+001,2,0,3.870968e+000,0.000000e+000,5.574121e-001,5.393301e-001,-7.234173e-001,-1.384665e+000,7.437437e-001,-5.190037e-001,-1.180251e+000,-4.571141e-005,-4.571040e-005,,,,,,,,,,,,,,,,,,,,
1607714345.467,,1.000000e+002,1.300516e+001,1.300475e+001,1,0,1.419355e+000,0.000000e+000,2.319524e+000,,,,,,,1.251360e-005,,,,,,,,,,,,,,,,,,,,,
1607714345.467,,1.000000e+002,1.300516e+001,1.300475e+001,1,0,3.096774e+000,0.000000e+000,2.017853e+000,,,,,,,1.936613e-006,,,,,,,,,,,,,,,,,,,,,
1607714345.467,,1.000000e+002,1.300475e+001,1.299894e+001,2,0,6.451613e-001,0.000000e+000,1.717708e+000,1.702907e+000,-4.156036e-001,-5.234177e-001,1.598061e+000,-5.204497e-001,-6.282638e-001,-1.444621e-005,-1.434489e-005,,,,,,,,,,,,,,,,,,,,
1607714345.467,,1.000000e+002,1.300475e+001,1.299894e+001,2,0,2.322581e+000,0.000000e+000,2.907912e+000,2.890059e+000,1.051865e+000,6.637342e-001,3.017983e+000,1.179789e+000,7.916582e-001,3.618268e-005,3.618000e-005,,,,,,,,,,,,,,,,,,,,
1607714345.467,,1.000000e+002,1.300475e+001,1.299894e+001,2,0,4.000000e+000,0.000000e+000,7.743954e-001,7.479973e-001,-8.098798e-001,-1.478327e+000,1.051304e+000,-5.065731e-001,-1.175021e+000,-4.964272e-005,-4.997494e-005,,,,,,,,,,,,,,,,,,,,
1607714455.817,,1.000000e+002,1.402150e+001,1.401561e+001,1,0,1.548387e+000,0.000000e+000,1.865721e+000,,,,,,,1.814352e-005,,,,,,,,,,,,,,,,,,,,,
1607714455.817,,1.000000e+002,1.402150e+001,1.401561e+001,1,0,3.225806e+000,0.000000e+000,1.206226e+000,,,,,,,-7.221766e-006,,,,,,,,,,,,,,,,,,,,,
1607714455.817,,1.000000e+002,1.401558e+001,1.400887e+001,2,0,7.741935e-001,0.000000e+000,1.170977e+000,1.154192e+000,-3.507605e-001,-4.786900e-001,1.006170e+000,-4.987830e-001,-6.267126e-001,-1.245512e-005,-1.250077e-005,,,,,,,,,,,,,,,,,,,,
1607714455.817,,1.000000e+002,1.401558e+001,1.400887e+001,2,0,2.451613e+000,0.000000e+000,2.310521e+000,2.292058e+000,1.064286e+000,6.591753e-001,2.340785e+000,1.113012e+000,7.079021e-001,3.598785e-005,3.589866e-005,,,,,,,,,,,,,,,,,,,,
1607714566.257,,1.000000e+002,1.498685e+001,1.499914e+001,1,0,0.000000e+000,0.000000e+000,2.203861e+000,,,,,,,-1.961124e-005,,,,,,,,,,,,,,,,,,,,,
1607714566.257,,1.000000e+002,1.498685e+001,1.499914e+001,1,0,1.677419e+000,0.000000e+000,3.183795e+000,,,,,,,2.226015e-005,,,,,,,,,,,,,,,,,,,,,
1607714566.257,,1.000000e+002,1.498685e+001,1.499914e+001,1,0,3.354839e+000,0.000000e+000,2.204776e+000,,,,,,,-1.629264e-005,,,,,,,,,,,,,,,,,,,,,
1607714566.257,,1.000000e+002,1.500237e+001,1.500431e+001,2,0,9.032258e-001,0.000000e+000,2.464180e+000,2.446479e+000,-2.584899e-001,-4.061453e-001,2.275119e+000,-4.298497e-001,-5.775051e-001,-9.522279e-006,-9.508120e-006,,,,,,,,,,,,,,,,,,,,
1607714566.257,,1.000000e+002,1.500237e+001,1.500431e+001,2,0,2.580645e+000,0.000000e+000,3.472190e+000,3.451972e+000,1.021221e+000,5.993481e-001,3.406121e+000,9.753692e-001,5.534966e-001,3.346492e-005,3.339416e-005,,,,,,,,,,,,,,,,,,,,
1607714684.257,,1.000000e+002,1.698474e+001,1.700055e+001,1,0,1.290323e-001,0.000000e+000,2.269627e+000,,,,,,,-2.003110e-005,,,,,,,,,,,,,,,,,,,,,
1607714684.257,,1.000000e+002,1.698474e+001,1.700055e+001,1,0,1.806452e+000,0.000000e+000,3.367514e+000,,,,,,,2.659157e-005,,,,,,,,,,,,,,,,,,,,,
1607714684.257,,1.000000e+002,1.698474e+001,1.700055e+001,1,0,3.483871e+000,0.000000e+000,2.079042e+000,,,,,,,-2.475698e-005,,,,,,,,,,,,,,,,,,,,,
1607714684.257,,1.000000e+002,1.700471e+001,1.700304e+001,2,0,1.032258e+000,0.000000e+000,2.635233e+000,2.618296e+000,-1.434023e-001,-3.097394e-001,2.440570e+000,-3.211283e-001,-4.874654e-001,-5.654409e-006,-5.616079e-006,,,,,,,,,,,,,,,,,,,,
1607714684.257,,1.000000e+002,1.700471e+001,1.700304e+001,2,0,2.709677e+000,0.000000e+000,3.429618e+000,3.416266e+000,9.248660e-001,4.882312e-001,3.292175e+000,8.007746e-001,3.641398e-001,2.850287e-005,2.869102e-005,,,,,,,,,,,,,,,,,,,,
1607714816.548,,1.000000e+002,1.899017e+001,1.899843e+001,1,0,2.580645e-001,0.000000e+000,1.712825e+000,,,,,,,-1.925214e-005,,,,,,,,,,,,,,,,,,,,,
1607714816.548,,1.000000e+002,1.899017e+001,1.899843e+001,1,0,1.935484e+000,0.000000e+000,2.885176e+000,,,,,,,3.044475e-005,,,,,,,,,,,,,,,,,,,,,
1607714816.548,,1.000000e+002,1.899017e+001,1.899843e+001,1,0,3.612903e+000,0.000000e+000,1.299153e+000,,,,,,,-3.310255e-005,,,,,,,,,,,,,,,,,,,,,
1607714816.548,,1.000000e+002,1.899946e+001,1.900566e+001,2,0,1.161290e+000,0.000000e+000,2.189364e+000,2.176699e+000,1.159140e-002,-1.750817e-001,1.991129e+000,-1.739788e-001,-3.606520e-001,-1.643493e-007,-2.439629e-008,,,,,,,,,,,,,,,,,,,,
1607714816.548,,1.000000e+002,1.899946e+001,1.900566e+001,2,0,2.838710e+000,0.000000e+000,2.676432e+000,2.658808e+000,7.633392e-001,3.070271e-001,2.494444e+000,5.989754e-001,1.426632e-001,2.135850e-005,2.131484e-005,,,,,,,,,,,,,,,,,,,,
1607714950.768,,1.000000e+002,2.098612e+001,2.098799e+001,1,0,3.870968e-001,0.000000e+000,2.087129e+000,,,,,,,-1.834196e-005,,,,,,,,,,,,,,,,,,,,,
1607714950.768,,1.000000e+002,2.098612e+001,2.098799e+001,1,0,2.064516e+000,0.000000e+000,3.311513e+000,,,,,,,3.349611e-005,,,,,,,,,,,,,,,,,,,,,
1607714950.768,,1.000000e+002,2.098612e+001,2.098799e+001,1,0,3.741935e+000,0.000000e+000,1.462882e+000,,,,,,,-4.082749e-005,,,,,,,,,,,,,,,,,,,,,
1607714950.768,,1.000000e+002,2.099298e+001,2.100920e+001,2,0,1.290323e+000,0.000000e+000,2.694743e+000,2.679484e+000,1.806110e-001,-2.824402e-002,2.495507e+000,-3.366612e-003,-2.122216e-001,6.141330e-006,6.168993e-006,,,,,,,,,,,,,,,,,,,,
1607714950.768,,1.000000e+002,2.099298e+001,2.100920e+001,2,0,2.967742e+000,0.000000e+000,2.816815e+000,2.799497e+000,5.721348e-001,9.176826e-002,2.623338e+000,3.959766e-001,-8.438993e-002,1.271161e-005,1.266106e-005,,,,,,,,,,,,,,,,,,,,
1607715088.348,,1.000000e+002,2.299213e+001,2.298918e+001,1,0,5.161290e-001,0.000000e+000,2.306859e+000,,,,,,,-1.722113e-005,,,,,,,,,,,,,,,,,,,,,
1607715088.348,,1.000000e+002,2.299213e+001,2.298918e+001,1,0,2.193548e+000,0.000000e+000,3.562524e+000,,,,,,,3.593547e-005,,,,,,,,,,,,,,,,,,,,,
1607715088.348,,1.000000e+002,2.299213e+001,2.298918e+001,1,0,3.870968e+000,0.000000e+000,1.496758e+000,,,,,,,-4.726827e-005,,,,,,,,,,,,,,,,,,,,,
1607715088.348,,1.000000e+002,2.298329e+001,2.299508e+001,2,0,1.419355e+000,0.000000e+000,3.046616e+000,3.027543e+000,3.546945e-001,1.234586e-001,2.858367e+000,1.855189e-001,-4.571700e-002,1.269473e-005,1.257128e-005,,,,,,,,,,,,,,,,,,,,
1607715088.348,,1.000000e+002,2.298329e+001,2.299508e+001,2,0,3.096774e+000,0.000000e+000,2.770275e+000,2.753872e+000,3.543026e-001,-1.502120e-001,2.596265e+000,1.966955e-001,-3.078191e-001,2.916626e-006,2.922141e-006,,,,,,,,,,,,,,,,,,,,
1607715227.488,,1.000000e+002,2.500259e+001,2.499743e+001,1,0,6.451613e-001,0.000000e+000,2.031281e+000,,,,,,,-1.563053e-005,,,,,,,,,,,,,,,,,,,,,
1607715227.488,,1.000000e+002,2.500259e+001,2.499743e+001,1,0,2.322581e+000,0.000000e+000,3.281453e+000,,,,,,,3.731649e-005,,,,,,,,,,,,,,,,,,,,,
1607715227.488,,1.000000e+002,2.500259e+001,2.499743e+001,1,0,4.000000e+000,0.000000e+000,1.059892e+000,,,,,,,-5.226742e-005,,,,,,,,,,,,,,,,,,,,,
1607715227.488,,1.000000e+002,2.499228e+001,2.498970e+001,2,0,1.548387e+000,0.000000e+000,2.881666e+000,2.865797e+000,5.252033e-001,2.718427e-001,2.731605e+000,3.910110e-001,1.376505e-001,1.878958e-005,1.882075e-005,,,,,,,,,,,,,,,,,,,,
1607715227.488,,1.000000e+002,2.499228e+001,2.498970e+001,2,0,3.225806e+000,0.000000e+000,2.218967e+000,2.203250e+000,1.371306e-001,-3.907039e-001,2.070378e+000,4.258452e-003,-5.235760e-001,-6.801216e-006,-6.761038e-006,,,,,,,,,,,,,,,,,,,,
1607715456.749,,1.000000e+002,2.297960e+001,2.298624e+001,1,0,7.741935e-001,0.000000e+000,2.778058e+000,,,,,,,-1.325939e-005,,,,,,,,,,,,,,,,,,,,,
1607715456.749,,1.000000e+002,2.297960e+001,2.298624e+001,1,0,2.451613e+000,0.000000e+000,3.957122e+000,,,,,,,3.678640e-005,,,,,,,,,,,,,,,,,,,,,
1607715456.749,,1.000000e+002,2.298181e+001,2.299951e+001,2,0,0.000000e+000,0.000000e+000,2.644388e+000,2.629358e+000,-6.556144e-001,-6.556144e-001,2.994143e+000,-2.908297e-001,-2.908297e-001,-2.074728e-005,-2.074265e-005,,,,,,,,,,,,,,,,,,,,
1607715456.749,,1.000000e+002,2.298181e+001,2.299951e+001,2,0,1.677419e+000,0.000000e+000,3.686732e+000,3.672236e+000,6.623648e-001,3.872635e-001,3.611222e+000,6.013504e-001,3.262491e-001,2.365679e-005,2.369769e-005,,,,,,,,,,,,,,,,,,,,
1607715456.749,,1.000000e+002,2.298181e+001,2.299951e+001,2,0,3.354839e+000,0.000000e+000,2.664378e+000,2.650874e+000,-8.389641e-002,-6.340990e-001,2.564881e+000,-1.698895e-001,-7.200921e-001,-1.670473e-005,-1.660874e-005,,,,,,,,,,,,,,,,,,,,
1607715677.469,,1.000000e+002,2.098986e+001,2.099236e+001,1,0,9.032258e-001,0.000000e+000,2.110780e+000,,,,,,,-9.913652e-006,,,,,,,,,,,,,,,,,,,,,
1607715677.469,,1.000000e+002,2.098986e+001,2.099236e+001,1,0,2.580645e+000,0.000000e+000,3.135729e+000,,,,,,,3.382040e-005,,,,,,,,,,,,,,,,,,,,,
1607715677.469,,1.000000e+002,2.099111e+001,2.098986e+001,2,0,1.290323e-001,0.000000e+000,1.895171e+000,1.879072e+000,-6.448212e-001,-6.661074e-001,2.170847e+000,-3.530465e-001,-3.743327e-001,-2.112550e-005,-2.098833e-005,,,,,,,,,,,,,,,,,,,,
1607715677.469,,1.000000e+002,2.099111e+001,2.098986e+001,2,0,1.806452e+000,0.000000e+000,3.046769e+000,3.028611e+000,7.814375e-001,4.834309e-001,3.054101e+000,8.069280e-001,5.089214e-001,2.778835e-005,2.785084e-005,,,,,,,,,,,,,,,,,,,,
1607715677.469,,1.000000e+002,2.099111e+001,2.098986e+001,2,0,3.483871e+000,0.000000e+000,1.715572e+000,1.691539e+000,-2.789139e-001,-8.536409e-001,1.650683e+000,-3.197702e-001,-8.944973e-001,-2.522818e-005,-2.539701e-005,,,,,,,,,,,,,,,,,,,,
1607715880.639,,1.000000e+002,1.899688e+001,1.899636e+001,1,0,1.032258e+000,0.000000e+000,2.236515e+000,,,,,,,-5.346490e-006,,,,,,,,,,,,,,,,,,,,,
1607715880.639,,1.000000e+002,1.899688e+001,1.899636e+001,1,0,2.709677e+000,0.000000e+000,3.031510e+000,,,,,,,2.895130e-005,,,,,,,,,,,,,,,,,,,,,
1607715880.639,,1.000000e+002,1.899636e+001,1.899688e+001,2,0,2.580645e-001,0.000000e+000,1.951019e+000,1.927138e+000,-5.973166e-001,-6.400355e-001,2.105542e+000,-4.189129e-001,-4.616318e-001,-1.970913e-005,-1.975166e-005,,,,,,,,,,,,,,,,,,,,
1607715880.639,,1.000000e+002,1.899636e+001,1.899688e+001,2,0,1.935484e+000,0.000000e+000,3.144121e+000,3.123293e+000,8.765112e-001,5.561192e-001,3.241669e+000,9.948877e-001,6.744957e-001,3.092465e-005,3.101152e-005,,,,,,,,,,,,,,,,,,,,
1607715880.639,,1.000000e+002,1.899636e+001,1.899688e+001,2,0,3.612903e+000,0.000000e+000,1.524376e+000,1.502632e+000,-4.664766e-001,-1.064542e+000,1.532123e+000,-4.369853e-001,-1.035050e+000,-3.392219e-005,-3.386880e-005,,,,,,,,,,,,,,,,,,,,
1607716046.379,,1.000000e+002,1.702890e+001,1.700846e+001,1,0,1.161290e+000,0.000000e+000,2.544595e+000,,,,,,,3.459281e-007,,,,,,,,,,,,,,,,,,,,,
1607716046.379,,1.000000e+002,1.702890e+001,1.700846e+001,1,0,2.838710e+000,0.000000e+000,3.008317e+000,,,,,,,2.117440e-005,,,,,,,,,,,,,,,,,,,,,
1607716046.379,,1.000000e+002,1.700846e+001,1.700013e+001,2,0,3.870968e-001,0.000000e+000,2.141909e+000,2.127642e+000,-5.489746e-001,-6.150465e-001,2.195156e+000,-4.814599e-001,-5.475318e-001,-1.840170e-005,-1.829289e-005,,,,,,,,,,,,,,,,,,,,
1607716046.379,,1.000000e+002,1.700846e+001,1.700013e+001,2,0,2.064516e+000,0.000000e+000,3.374380e+000,3.358968e+000,9.686639e-001,6.162803e-001,3.534863e+000,1.144558e+000,7.921743e-001,3.397035e-005,3.404079e-005,,,,,,,,,,,,,,,,,,,,
1607716046.379,,1.000000e+002,1.700846e+001,1.700013e+001,2,0,3.741935e+000,0.000000e+000,1.495842e+000,1.475700e+000,-6.282931e-001,-1.266988e+000,1.590987e+000,-5.130062e-001,-1.151701e+000,-4.137916e-005,-4.149431e-005,,,,,,,,,,,,,,,,,,,,
1607716206.960,,1.000000e+002,1.501890e+001,1.501144e+001,1,0,1.290323e+000,0.000000e+000,2.440223e+000,,,,,,,6.947608e-006,,,,,,,,,,,,,,,,,,,,,
1607716206.960,,1.000000e+002,1.501890e+001,1.501144e+001,1,0,2.967742e+000,0.000000e+000,2.510567e+000,,,,,,,1.174142e-005,,,,,,,,,,,,,,,,,,,,,
1607716206.960,,1.000000e+002,1.500237e+001,1.499784e+001,2,0,5.161290e-001,0.000000e+000,1.922484e+000,1.905547e+000,-4.919800e-001,-5.820253e-001,1.870070e+000,-5.274566e-001,-6.175020e-001,-1.657629e-005,-1.657731e-005,,,,,,,,,,,,,,,,,,,,
1607716206.960,,1.000000e+002,1.500237e+001,1.499784e+001,2,0,2.193548e+000,0.000000e+000,3.163195e+000,3.148165e+000,1.043286e+000,6.605933e-001,3.332739e+000,1.227859e+000,8.451667e-001,3.623505e-005,3.632810e-005,,,,,,,,,,,,,,,,,,,,
1607716206.960,,1.000000e+002,1.500237e+001,1.499784e+001,2,0,3.870968e+000,0.000000e+000,1.072099e+000,1.056077e+000,-7.561551e-001,-1.431495e+000,1.270811e+000,-5.414209e-001,-1.216761e+000,-4.773996e-005,-4.767187e-005,,,,,,,,,,,,,,,,,,,,
1607716325.420,,1.000000e+002,1.401725e+001,1.400947e+001,1,0,1.419355e+000,0.000000e+000,2.586099e+000,,,,,,,1.306286e-005,,,,,,,,,,,,,,,,,,,,,
1607716325.420,,1.000000e+002,1.401725e+001,1.400947e+001,1,0,3.096774e+000,0.000000e+000,2.260624e+000,,,,,,,1.685999e-006,,,,,,,,,,,,,,,,,,,,,
1607716325.420,,1.000000e+002,1.400947e+001,1.400904e+001,2,0,6.451613e-001,0.000000e+000,1.967651e+000,1.951095e+000,-4.275398e-001,-5.414708e-001,1.838580e+000,-5.400544e-001,-6.539854e-001,-1.467514e-005,-1.463912e-005,,,,,,,,,,,,,,,,,,,,
1607716325.420,,1.000000e+002,1.400947e+001,1.400904e+001,2,0,2.322581e+000,0.000000e+000,3.188830e+000,3.170825e+000,1.088410e+000,6.782591e-001,3.305400e+000,1.222986e+000,8.128345e-001,3.741581e-005,3.740713e-005,,,,,,,,,,,,,,,,,,,,
1607716325.420,,1.000000e+002,1.400947e+001,1.400904e+001,2,0,4.000000e+000,0.000000e+000,9.591821e-001,9.418632e-001,-8.443307e-001,-1.550702e+000,1.261643e+000,-5.245509e-001,-1.230923e+000,-5.216589e-005,-5.213160e-005,,,,,,,,,,,,,,,,,,,,
1607716449.020,,1.000000e+002,1.301480e+001,1.300936e+001,1,0,1.548387e+000,0.000000e+000,2.829938e+000,,,,,,,1.902701e-005,,,,,,,,,,,,,,,,,,,,,
1607716449.020,,1.000000e+002,1.301480e+001,1.300936e+001,1,0,3.225806e+000,0.000000e+000,2.103609e+000,,,,,,,-8.684336e-006,,,,,,,,,,,,,,,,,,,,,
1607716449.020,,1.000000e+002,1.300887e+001,1.300813e+001,2,0,7.741935e-001,0.000000e+000,2.131380e+000,2.113069e+000,-3.481296e-001,-4.878755e-001,1.953175e+000,-5.080238e-001,-6.477697e-001,-1.196453e-005,-1.204648e-005,,,,,,,,,,,,,,,,,,,,
1607716449.020,,1.000000e+002,1.300887e+001,1.300813e+001,2,0,2.451613e+000,0.000000e+000,3.270314e+000,3.253071e+000,1.094655e+000,6.521261e-001,3.291708e+000,1.133292e+000,6.907637e-001,3.687368e-005,3.684970e-005,,,,,,,,,,,,,,,,,,,,
1607716571.240,,1.000000e+002,1.201011e+001,1.200752e+001,1,0,0.000000e+000,0.000000e+000,1.989624e+000,,,,,,,-2.141362e-005,,,,,,,,,,,,,,,,,,,,,
1607716571.240,,1.000000e+002,1.201011e+001,1.200752e+001,1,0,1.677419e+000,0.000000e+000,3.056382e+000,,,,,,,2.468987e-005,,,,,,,,,,,,,,,,,,,,,
1607716571.240,,1.000000e+002,1.201011e+001,1.200752e+001,1,0,3.354839e+000,0.000000e+000,1.942016e+000,,,,,,,-1.875205e-005,,,,,,,,,,,,,,,,,,,,,
1607716571.240,,1.000000e+002,1.200699e+001,1.200354e+001,2,0,9.032258e-001,0.000000e+000,2.310826e+000,2.295872e+000,-2.385632e-001,-4.061258e-001,2.112708e+000,-4.217276e-001,-5.892901e-001,-8.235744e-006,-8.223775e-006,,,,,,,,,,,,,,,,,,,,
1607716571.240,,1.000000e+002,1.200699e+001,1.200354e+001,2,0,2.580645e+000,0.000000e+000,3.274128e+000,3.257496e+000,1.034248e+000,5.554976e-001,3.190961e+000,9.677131e-001,4.889629e-001,3.358399e-005,3.354524e-005,,,,,,,,,,,,,,,,,,,,
1607716701.480,,1.000000e+002,1.100988e+001,1.100725e+001,1,0,1.290323e-001,0.000000e+000,2.192569e+000,,,,,,,-2.182375e-005,,,,,,,,,,,,,,,,,,,,,
1607716701.480,,1.000000e+002,1.100988e+001,1.100725e+001,1,0,1.806452e+000,0.000000e+000,3.394827e+000,,,,,,,3.025969e-005,,,,,,,,,,,,,,,,,,,,,
1607716701.480,,1.000000e+002,1.100988e+001,1.100725e+001,1,0,3.483871e+000,0.000000e+000,1.894408e+000,,,,,,,-2.861452e-005,,,,,,,,,,,,,,,,,,,,,
1607716701.480,,1.000000e+002,1.100708e+001,1.100782e+001,2,0,1.032258e+000,0.000000e+000,2.664531e+000,2.650340e+000,-7.385354e-002,-2.721863e-001,2.460602e+000,-2.635913e-001,-4.619241e-001,-2.273882e-006,-2.209628e-006,,,,,,,,,,,,,,,,,,,,
1607716701.480,,1.000000e+002,1.100708e+001,1.100782e+001,2,0,2.709677e+000,0.000000e+000,3.303273e+000,3.286259e+000,8.843567e-001,3.637333e-001,3.129379e+000,7.274766e-001,2.068532e-001,2.663370e-005,2.660250e-005,,,,,,,,,,,,,,,,,,,,
1607716835.090,,1.000000e+002,1.000593e+001,9.999912e+000,1,0,2.580645e-001,0.000000e+000,2.112001e+000,,,,,,,-2.204733e-005,,,,,,,,,,,,,,,,,,,,,
1607716835.090,,1.000000e+002,1.000593e+001,9.999912e+000,1,0,1.935484e+000,0.000000e+000,3.432059e+000,,,,,,,3.563541e-005,,,,,,,,,,,,,,,,,,,,,
1607716835.090,,1.000000e+002,1.000593e+001,9.999912e+000,1,0,3.612903e+000,0.000000e+000,1.541161e+000,,,,,,,-3.850665e-005,,,,,,,,,,,,,,,,,,,,,
1607716835.090,,1.000000e+002,1.000236e+001,1.000013e+001,2,0,1.161290e+000,0.000000e+000,2.834211e+000,2.819638e+000,2.027010e-001,-3.138232e-002,2.608637e+000,-8.300619e-003,-2.423840e-001,8.229224e-006,8.256851e-006,,,,,,,,,,,,,,,,,,,,
1607716835.090,,1.000000e+002,1.000236e+001,1.000013e+001,2,0,2.838710e+000,0.000000e+000,2.925154e+000,2.907988e+000,6.291712e-001,5.696750e-002,2.697388e+000,4.185716e-001,-1.536322e-001,1.539706e-005,1.534519e-005,,,,,,,,,,,,,,,,,,,,
1607716964.611,,1.000000e+002,9.008808e+000,9.004873e+000,1,0,3.870968e-001,0.000000e+000,1.594415e+000,,,,,,,-2.020008e-005,,,,,,,,,,,,,,,,,,,,,
1607716964.611,,1.000000e+002,9.008808e+000,9.004873e+000,1,0,2.064516e+000,0.000000e+000,2.914015e+000,,,,,,,3.814645e-005,,,,,,,,,,,,,,,,,,,,,
1607716964.611,,1.000000e+002,9.008808e+000,9.004873e+000,1,0,3.741935e+000,0.000000e+000,7.490654e-001,,,,,,,-4.656415e-005,,,,,,,,,,,,,,,,,,,,,
1607716964.611,,1.000000e+002,9.005945e+000,9.002012e+000,2,0,1.290323e+000,0.000000e+000,2.548409e+000,2.530327e+000,5.019534e-001,2.298050e-001,2.318521e+000,2.901473e-001,1.799893e-002,1.946627e-005,1.959661e-005,,,,,,,,,,,,,,,,,,,,
1607716964.611,,1.000000e+002,9.005945e+000,9.002012e+000,2,0,2.967742e+000,0.000000e+000,2.044404e+000,2.016098e+000,3.415173e-001,-2.844241e-001,1.797447e+000,1.228660e-001,-5.030754e-001,2.925153e-006,2.645807e-006,,,,,,,,,,,,,,,,,,,,
1607717093.401,,1.000000e+002,8.008183e+000,8.005653e+000,1,0,5.161290e-001,0.000000e+000,2.530709e+000,,,,,,,-1.608345e-005,,,,,,,,,,,,,,,,,,,,,
1607717093.401,,1.000000e+002,8.008183e+000,8.005653e+000,1,0,2.193548e+000,0.000000e+000,3.743954e+000,,,,,,,3.844505e-005,,,,,,,,,,,,,,,,,,,,,
1607717093.401,,1.000000e+002,8.008183e+000,8.005653e+000,1,0,3.870968e+000,0.000000e+000,1.409018e+000,,,,,,,-5.269592e-005,,,,,,,,,,,,,,,,,,,,,
1607717093.401,,1.000000e+002,8.005373e+000,8.002005e+000,2,0,1.419355e+000,0.000000e+000,3.599756e+000,3.582437e+000,7.433870e-001,4.253535e-001,3.408683e+000,5.696333e-001,2.515998e-001,2.854102e-005,2.873299e-005,,,,,,,,,,,,,,,,,,,,
1607717093.401,,1.000000e+002,8.005373e+000,8.002005e+000,2,0,3.096774e+000,0.000000e+000,2.556191e+000,2.532006e+000,6.881359e-002,-6.250777e-001,2.347469e+000,-1.157229e-001,-8.096142e-001,-9.624462e-006,-9.693715e-006,,,,,,,,,,,,,,,,,,,,
1607717223.211,,1.000000e+002,7.006482e+000,7.005205e+000,1,0,6.451613e-001,0.000000e+000,2.222629e+000,,,,,,,-1.007081e-005,,,,,,,,,,,,,,,,,,,,,
1607717223.211,,1.000000e+002,7.006482e+000,7.005205e+000,1,0,2.322581e+000,0.000000e+000,3.235981e+000,,,,,,,3.682262e-005,,,,,,,,,,,,,,,,,,,,,
1607717223.211,,1.000000e+002,7.006482e+000,7.005205e+000,1,0,4.000000e+000,0.000000e+000,8.175784e-001,,,,,,,-5.717356e-005,,,,,,,,,,,,,,,,,,,,,
1607717223.211,,1.000000e+002,7.005205e+000,7.000952e+000,2,0,1.548387e+000,0.000000e+000,3.277485e+000,3.263447e+000,9.105626e-001,5.321994e-001,3.185557e+000,8.326722e-001,4.543090e-001,3.491582e-005,3.492396e-005,,,,,,,,,,,,,,,,,,,,
1607717223.211,,1.000000e+002,7.005205e+000,7.000952e+000,2,0,3.225806e+000,0.000000e+000,1.796750e+000,1.780423e+000,-1.625684e-001,-9.508252e-001,1.630957e+000,-3.120345e-001,-1.100291e+000,-2.059700e-005,-2.067670e-005,,,,,,,,,,,,,,,,,,,,
1607717352.451,,1.000000e+002,6.003036e+000,6.001380e+000,1,0,7.741935e-001,0.000000e+000,2.359350e+000,,,,,,,-3.072069e-006,,,,,,,,,,,,,,,,,,,,,
1607717352.451,,1.000000e+002,6.003036e+000,6.001380e+000,1,0,2.451613e+000,0.000000e+000,3.087053e+000,,,,,,,3.295745e-005,,,,,,,,,,,,,,,,,,,,,
1607717352.451,,1.000000e+002,6.002886e+000,5.998972e+000,2,0,0.000000e+000,0.000000e+000,1.707485e+000,1.717861e+000,-1.014595e+000,-1.014595e+000,2.284061e+000,-4.483943e-001,-4.483943e-001,-3.126601e-005,-3.154425e-005,,,,,,,,,,,,,,,,,,,,
1607717352.451,,1.000000e+002,6.002886e+000,5.998972e+000,2,0,1.677419e+000,0.000000e+000,3.246968e+000,3.271077e+000,1.009178e+000,5.386209e-001,3.321998e+000,1.060100e+000,5.895424e-001,3.813118e-005,3.839661e-005,,,,,,,,,,,,,,,,,,,,
1607717352.451,,1.000000e+002,6.002886e+000,5.998972e+000,2,0,3.354839e+000,0.000000e+000,1.411002e+000,1.430381e+000,-3.609602e-001,-1.302075e+000,1.331649e+000,-4.596916e-001,-1.400806e+000,-3.104963e-005,-3.099855e-005,,,,,,,,,,,,,,,,,,,,
1607717508.161,,1.000000e+002,5.000204e+000,4.997972e+000,1,0,9.032258e-001,0.000000e+000,3.059281e+000,,,,,,,3.662775e-006,,,,,,,,,,,,,,,,,,,,,
1607717508.161,,1.000000e+002,5.000204e+000,4.997972e+000,1,0,2.580645e+000,0.000000e+000,3.461814e+000,,,,,,,2.685735e-005,,,,,,,,,,,,,,,,,,,,,
1607717508.161,,1.000000e+002,4.997972e+000,4.996421e+000,2,0,1.290323e-001,0.000000e+000,2.445716e+000,2.419776e+000,-8.976192e-001,-9.364026e-001,2.799592e+000,-5.178034e-001,-5.565867e-001,-2.671493e-005,-2.672485e-005,,,,,,,,,,,,,,,,,,,,
1607717508.161,,1.000000e+002,4.997972e+000,4.996421e+000,2,0,1.806452e+000,0.000000e+000,3.895323e+000,3.868773e+000,1.055561e+000,5.125942e-001,4.046604e+000,1.233392e+000,6.904254e-001,3.946254e-005,3.942977e-005,,,,,,,,,,,,,,,,,,,,
1607717508.161,,1.000000e+002,4.997972e+000,4.996421e+000,2,0,3.483871e+000,0.000000e+000,1.809415e+000,1.784695e+000,-5.243333e-001,-1.571483e+000,1.756258e+000,-5.527706e-001,-1.599920e+000,-3.950950e-005,-3.946490e-005,,,,,,,,,,,,,,,,,,,,
1607717653.862,,1.000000e+002,4.002535e+000,4.001751e+000,1,0,1.032258e+000,0.000000e+000,3.013352e+000,,,,,,,1.197463e-005,,,,,,,,,,,,,,,,,,,,,
1607717653.862,,1.000000e+002,4.002535e+000,4.001751e+000,1,0,2.709677e+000,0.000000e+000,2.934615e+000,,,,,,,1.676597e-005,,,,,,,,,,,,,,,,,,,,,
1607717653.862,,1.000000e+002,4.001079e+000,4.002983e+000,2,0,2.580645e-001,0.000000e+000,2.428931e+000,2.413825e+000,-7.081372e-001,-8.008404e-001,2.564425e+000,-5.575363e-001,-6.502395e-001,-1.725496e-005,-1.710861e-005,,,,,,,,,,,,,,,,,,,,
1607717653.862,,1.000000e+002,4.001079e+000,4.002983e+000,2,0,1.935484e+000,0.000000e+000,3.591363e+000,3.572061e+000,1.052669e+000,3.573956e-001,3.823572e+000,1.304181e+000,6.089070e-001,3.854765e-005,3.849398e-005,,,,,,,,,,,,,,,,,,,,
1607717653.862,,1.000000e+002,4.001079e+000,4.002983e+000,2,0,3.612903e+000,0.000000e+000,1.285573e+000,1.274510e+000,-6.423109e-001,-1.940155e+000,1.339163e+000,-5.776576e-001,-1.875502e+000,-4.803663e-005,-4.777971e-005,,,,,,,,,,,,,,,,,,,,
1607717741.462,,1.000000e+002,3.875279e+000,3.874660e+000,1,0,1.161290e+000,0.000000e+000,2.410925e+000,,,,,,,1.849410e-005,,,,,,,,,,,,,,,,,,,,,
1607717741.462,,1.000000e+002,3.875279e+000,3.874660e+000,1,0,2.838710e+000,0.000000e+000,1.899291e+000,,,,,,,5.796290e-006,,,,,,,,,,,,,,,,,,,,,
1607717741.462,,1.000000e+002,3.880443e+000,3.878995e+000,2,0,3.870968e-001,0.000000e+000,1.821470e+000,1.803769e+000,-5.389658e-001,-6.815107e-001,1.762658e+000,-5.800774e-001,-7.226223e-001,-1.114498e-005,-1.106914e-005,,,,,,,,,,,,,,,,,,,,
1607717741.462,,1.000000e+002,3.880443e+000,3.878995e+000,2,0,2.064516e+000,0.000000e+000,2.819867e+000,2.799039e+000,1.073998e+000,3.137591e-001,3.045238e+000,1.320197e+000,5.599582e-001,3.809042e-005,3.806820e-005,,,,,,,,,,,,,,,,,,,,
1607717741.462,,1.000000e+002,3.880443e+000,3.878995e+000,2,0,3.741935e+000,0.000000e+000,3.918517e-001,3.710231e-001,-7.363231e-001,-2.114257e+000,5.381092e-001,-5.692370e-001,-1.947171e+000,-5.334453e-005,-5.333640e-005,,,,,,,,,,,,,,,,,,,,
1607717827.642,,1.000000e+002,3.749794e+000,3.752637e+000,1,0,1.290323e+000,0.000000e+000,3.577783e+000,,,,,,,2.520336e-005,,,,,,,,,,,,,,,,,,,,,
1607717827.642,,1.000000e+002,3.749794e+000,3.752637e+000,1,0,2.967742e+000,0.000000e+000,2.597391e+000,,,,,,,-6.385322e-006,,,,,,,,,,,,,,,,,,,,,
1607717827.642,,1.000000e+002,3.751120e+000,3.751689e+000,2,0,5.161290e-001,0.000000e+000,2.937057e+000,2.936828e+000,-3.806489e-001,-5.762966e-001,2.763998e+000,-5.534793e-001,-7.491269e-001,-5.717418e-006,-5.417518e-006,,,,,,,,,,,,,,,,,,,,
1607717827.642,,1.000000e+002,3.751120e+000,3.751689e+000,2,0,2.193548e+000,0.000000e+000,3.772335e+000,3.761654e+000,1.080032e+000,2.485294e-001,3.917519e+000,1.235897e+000,4.043944e-001,3.698157e-005,3.697941e-005,,,,,,,,,,,,,,,,,,,,
1607717827.642,,1.000000e+002,3.751120e+000,3.751689e+000,2,0,3.870968e+000,0.000000e+000,1.268025e+000,1.253681e+000,-7.920859e-001,-2.259443e+000,1.524802e+000,-5.209653e-001,-1.988323e+000,-5.742526e-005,-5.745071e-005,,,,,,,,,,,,,,,,,,,,
1607717915.432,,1.000000e+002,3.624221e+000,3.623788e+000,1,0,1.419355e+000,0.000000e+000,3.003433e+000,,,,,,,2.999470e-005,,,,,,,,,,,,,,,,,,,,,
1607717915.432,,1.000000e+002,3.624221e+000,3.623788e+000,1,0,3.096774e+000,0.000000e+000,1.636377e+000,,,,,,,-1.748335e-005,,,,,,,,,,,,,,,,,,,,,
1607717915.432,,1.000000e+002,3.624134e+000,3.628470e+000,2,0,6.451613e-001,0.000000e+000,2.383154e+000,2.366446e+000,-2.407345e-001,-4.890237e-001,2.129750e+000,-4.774298e-001,-7.257190e-001,-6.783521e-007,-7.557246e-007,,,,,,,,,,,,,,,,,,,,
1607717915.432,,1.000000e+002,3.624134e+000,3.628470e+000,2,0,2.322581e+000,0.000000e+000,3.041428e+000,3.019379e+000,1.057751e+000,1.639099e-001,3.040518e+000,1.078890e+000,1.850491e-001,3.501293e-005,3.470629e-005,,,,,,,,,,,,,,,,,,,,
1607717915.432,,1.000000e+002,3.624134e+000,3.628470e+000,2,0,4.000000e+000,0.000000e+000,5.328450e-001,5.191882e-001,-7.968880e-001,-2.336281e+000,8.628464e-001,-4.532298e-001,-1.992623e+000,-5.931017e-005,-5.928226e-005,,,,,,,,,,,,,,,,,,,,
1607718002.212,,1.000000e+002,3.491939e+000,3.492802e+000,1,0,1.548387e+000,0.000000e+000,3.310903e+000,,,,,,,3.417513e-005,,,,,,,,,,,,,,,,,,,,,
1607718002.212,,1.000000e+002,3.491939e+000,3.492802e+000,1,0,3.225806e+000,0.000000e+000,1.569848e+000,,,,,,,-2.834891e-005,,,,,,,,,,,,,,,,,,,,,
1607718002.212,,1.000000e+002,3.492802e+000,3.492017e+000,2,0,7.741935e-001,0.000000e+000,2.694743e+000,2.683757e+000,-1.058157e-001,-4.126289e-001,2.431082e+000,-3.584903e-001,-6.653035e-001,3.787442e-006,3.815716e-006,,,,,,,,,,,,,,,,,,,,
1607718002.212,,1.000000e+002,3.492802e+000,3.492017e+000,2,0,2.451613e+000,0.000000e+000,3.136645e+000,3.127108e+000,1.002297e+000,3.072190e-002,3.005807e+000,8.809966e-001,-9.057856e-002,3.081237e-005,3.093597e-005,,,,,,,,,,,,,,,,,,,,
1607718089.422,,1.000000e+002,3.367893e+000,3.367252e+000,1,0,0.000000e+000,0.000000e+000,1.766384e+000,,,,,,,-2.761875e-005,,,,,,,,,,,,,,,,,,,,,
1607718089.422,,1.000000e+002,3.367893e+000,3.367252e+000,1,0,1.677419e+000,0.000000e+000,3.100328e+000,,,,,,,3.632053e-005,,,,,,,,,,,,,,,,,,,,,
1607718089.422,,1.000000e+002,3.367893e+000,3.367252e+000,1,0,3.354839e+000,0.000000e+000,1.089799e+000,,,,,,,-3.704647e-005,,,,,,,,,,,,,,,,,,,,,
1607718089.422,,1.000000e+002,3.367252e+000,3.368250e+000,2,0,9.032258e-001,0.000000e+000,2.556497e+000,2.541695e+000,3.501867e-002,-3.308802e-001,2.304339e+000,-2.023375e-001,-5.682364e-001,8.380885e-006,8.462412e-006,,,,,,,,,,,,,,,,,,,,
1607718089.422,,1.000000e+002,3.367252e+000,3.368250e+000,2,0,2.580645e+000,0.000000e+000,2.730907e+000,2.709850e+000,8.826995e-001,-1.627257e-001,2.487052e+000,6.599019e-001,-3.855233e-001,2.463808e-005,2.450166e-005,,,,,,,,,,,,,,,,,,,,
1607718179.712,,1.000000e+002,3.243333e+000,3.244750e+000,1,0,1.290323e-001,0.000000e+000,2.109255e+000,,,,,,,-1.975828e-005,,,,,,,,,,,,,,,,,,,,,
1607718179.712,,1.000000e+002,3.243333e+000,3.244750e+000,1,0,1.806452e+000,0.000000e+000,3.268482e+000,,,,,,,3.756079e-005,,,,,,,,,,,,,,,,,,,,,
1607718179.712,,1.000000e+002,3.243333e+000,3.244750e+000,1,0,3.483871e+000,0.000000e+000,1.017624e+000,,,,,,,-4.512019e-005,,,,,,,,,,,,,,,,,,,,,
1607718179.712,,1.000000e+002,3.244106e+000,3.245008e+000,2,0,1.032258e+000,0.000000e+000,2.792554e+000,2.799878e+000,1.913440e-001,-2.429605e-001,2.588198e+000,-2.033618e-002,-4.546406e-001,1.360704e-005,1.387029e-005,,,,,,,,,,,,,,,,,,,,
1607718179.712,,1.000000e+002,3.244106e+000,3.245008e+000,2,0,2.709677e+000,0.000000e+000,2.599985e+000,2.596094e+000,6.933042e-001,-4.467449e-001,2.337643e+000,4.348537e-001,-7.051954e-001,1.501160e-005,1.502287e-005,,,,,,,,,,,,,,,,,,,,
1607718269.512,,1.000000e+002,3.118553e+000,3.119074e+000,1,0,2.580645e-001,0.000000e+000,2.005035e+000,,,,,,,-1.202749e-005,,,,,,,,,,,,,,,,,,,,,
1607718269.512,,1.000000e+002,3.118553e+000,3.119074e+000,1,0,1.935484e+000,0.000000e+000,2.973983e+000,,,,,,,3.749167e-005,,,,,,,,,,,,,,,,,,,,,
1607718269.512,,1.000000e+002,3.118553e+000,3.119074e+000,1,0,3.612903e+000,0.000000e+000,5.969329e-001,,,,,,,-5.035810e-005,,,,,,,,,,,,,,,,,,,,,
1607718269.512,,1.000000e+002,3.119074e+000,3.123189e+000,2,0,1.161290e+000,0.000000e+000,2.654917e+000,2.649271e+000,3.498432e-001,-1.493447e-001,2.465763e+000,1.663350e-001,-3.328528e-001,1.883591e-005,1.913489e-005,,,,,,,,,,,,,,,,,,,,
1607718269.512,,1.000000e+002,3.119074e+000,3.123189e+000,2,0,2.838710e+000,0.000000e+000,2.070191e+000,2.049210e+000,4.708312e-001,-7.494059e-001,1.809432e+000,2.310524e-001,-9.891846e-001,4.474088e-006,4.191177e-006,,,,,,,,,,,,,,,,,,,,
1607718359.713,,1.000000e+002,2.993731e+000,2.994816e+000,1,0,3.870968e-001,0.000000e+000,2.652171e+000,,,,,,,-5.253576e-006,,,,,,,,,,,,,,,,,,,,,
1607718359.713,,1.000000e+002,2.993731e+000,2.994816e+000,1,0,2.064516e+000,0.000000e+000,3.420462e+000,,,,,,,3.627506e-005,,,,,,,,,,,,,,,,,,,,,
1607718359.713,,1.000000e+002,2.993731e+000,2.994816e+000,1,0,3.741935e+000,0.000000e+000,9.617761e-001,,,,,,,-5.467889e-005,,,,,,,,,,,,,,,,,,,,,
1607718359.713,,1.000000e+002,2.995489e+000,2.999063e+000,2,0,1.290323e+000,0.000000e+000,3.291371e+000,3.271229e+000,5.159661e-001,-4.949403e-002,3.127988e+000,3.727249e-001,-1.927352e-001,2.458757e-005,2.464988e-005,,,,,,,,,,,,,,,,,,,,
1607718359.713,,1.000000e+002,2.995489e+000,2.999063e+000,2,0,2.967742e+000,0.000000e+000,2.254826e+000,2.224155e+000,2.039898e-001,-1.096568e+000,2.047516e+000,2.735072e-002,-1.273207e+000,-8.113871e-006,-8.417293e-006,,,,,,,,,,,,,,,,,,,,
1607718451.003,,1.000000e+002,2.869518e+000,2.870803e+000,1,0,5.161290e-001,0.000000e+000,2.763714e+000,,,,,,,6.806949e-007,,,,,,,,,,,,,,,,,,,,,
1607718451.003,,1.000000e+002,2.869518e+000,2.870803e+000,1,0,2.193548e+000,0.000000e+000,3.353323e+000,,,,,,,3.519357e-005,,,,,,,,,,,,,,,,,,,,,
1607718451.003,,1.000000e+002,2.869518e+000,2.870803e+000,1,0,3.870968e+000,0.000000e+000,8.328375e-001,,,,,,,-5.797752e-005,,,,,,,,,,,,,,,,,,,,,
1607718451.003,,1.000000e+002,2.870803e+000,2.874255e+000,2,0,1.419355e+000,0.000000e+000,3.365072e+000,3.345846e+000,6.583014e-001,1.727200e-002,3.267224e+000,5.796800e-001,-6.134939e-002,2.903031e-005,2.918533e-005,,,,,,,,,,,,,,,,,,,,
1607718451.003,,1.000000e+002,2.870803e+000,2.874255e+000,2,0,3.096774e+000,0.000000e+000,1.904173e+000,1.876707e+000,-5.325708e-002,-1.451867e+000,1.779606e+000,-1.503581e-001,-1.548968e+000,-2.079096e-005,-2.089863e-005,,,,,,,,,,,,,,,,,,,,
1607718541.683,,1.000000e+002,2.743229e+000,2.744120e+000,1,0,6.451613e-001,0.000000e+000,3.146715e+000,,,,,,,5.447771e-006,,,,,,,,,,,,,,,,,,,,,
1607718541.683,,1.000000e+002,2.743229e+000,2.744120e+000,1,0,2.322581e+000,0.000000e+000,3.552758e+000,,,,,,,3.272886e-005,,,,,,,,,,,,,,,,,,,,,
1607718541.683,,1.000000e+002,2.743229e+000,2.744120e+000,1,0,4.000000e+000,0.000000e+000,1.050889e+000,,,,,,,-5.937350e-005,,,,,,,,,,,,,,,,,,,,,
1607718541.683,,1.000000e+002,2.745092e+000,2.748747e+000,2,0,1.548387e+000,0.000000e+000,3.700160e+000,3.684672e+000,7.777741e-001,5.777311e-002,3.689000e+000,7.821021e-001,6.210113e-002,3.280357e-005,3.270742e-005,,,,,,,,,,,,,,,,,,,,
1607718541.683,,1.000000e+002,2.745092e+000,2.748747e+000,2,0,3.225806e+000,0.000000e+000,1.878691e+000,1.862135e+000,-2.647625e-001,-1.764765e+000,1.823313e+000,-3.035846e-001,-1.803587e+000,-3.148324e-005,-3.156421e-005,,,,,,,,,,,,,,,,,,,,
1607718634.223,,1.000000e+002,2.622482e+000,2.622340e+000,1,0,7.741935e-001,0.000000e+000,2.824445e+000,,,,,,,9.181371e-006,,,,,,,,,,,,,,,,,,,,,
1607718634.223,,1.000000e+002,2.622482e+000,2.622340e+000,1,0,2.451613e+000,0.000000e+000,3.033494e+000,,,,,,,2.877321e-005,,,,,,,,,,,,,,,,,,,,,
1607718634.223,,1.000000e+002,2.622340e+000,2.622696e+000,2,0,0.000000e+000,0.000000e+000,2.173800e+000,2.156710e+000,-1.116662e+000,-1.116662e+000,2.866188e+000,-4.071839e-001,-4.071839e-001,-2.443524e-005,-2.422521e-005,,,,,,,,,,,,,,,,,,,,
1607718634.223,,1.000000e+002,2.622340e+000,2.622696e+000,2,0,1.677419e+000,0.000000e+000,3.353781e+000,3.326848e+000,8.634496e-001,5.347657e-002,3.428476e+000,9.650775e-001,1.551044e-001,3.492215e-005,3.477600e-005,,,,,,,,,,,,,,,,,,,,
1607718634.223,,1.000000e+002,2.622340e+000,2.622696e+000,2,0,3.354839e+000,0.000000e+000,1.252460e+000,1.226673e+000,-4.267527e-001,-2.046699e+000,1.232023e+000,-4.214028e-001,-2.041349e+000,-4.043324e-005,-4.048453e-005,,,,,,,,,,,,,,,,,,,,
1607718858.743,,1.000000e+002,2.495014e+000,2.507484e+000,1,0,9.032258e-001,0.000000e+000,2.701610e+000,,,,,,,1.288517e-005,,,,,,,,,,,,,,,,,,,,,
1607718858.743,,1.000000e+002,2.495014e+000,2.507484e+000,1,0,2.580645e+000,0.000000e+000,2.641337e+000,,,,,,,2.185469e-005,,,,,,,,,,,,,,,,,,,,,
1607718858.743,,1.000000e+002,2.500597e+000,2.516107e+000,2,0,1.290323e-001,0.000000e+000,2.402991e+000,2.279469e+000,-8.713776e-001,-9.368052e-001,2.686978e+000,-4.638688e-001,-5.292964e-001,-1.435266e-005,-1.457568e-005,,,,,,,,,,,,,,,,,,,,
1607718858.743,,1.000000e+002,2.500597e+000,2.516107e+000,2,0,1.806452e+000,0.000000e+000,3.327993e+000,3.213016e+000,9.127280e-001,-3.258228e-003,3.404305e+000,1.104017e+000,1.880305e-001,3.523720e-005,3.527991e-005,,,,,,,,,,,,,,,,,,,,
1607718858.743,,1.000000e+002,2.500597e+000,2.516107e+000,2,0,3.483871e+000,0.000000e+000,1.016403e+000,9.067674e-001,-5.429621e-001,-2.309507e+000,9.548298e-001,-4.948997e-001,-2.261445e+000,-4.805022e-005,-4.787333e-005,,,,,,,,,,,,,,,,,,,,
1607719087.056,,1.000000e+002,2.371713e+000,2.388699e+000,1,0,1.032258e+000,0.000000e+000,2.734722e+000,,,,,,,1.642959e-005,,,,,,,,,,,,,,,,,,,,,
1607719087.056,,1.000000e+002,2.371713e+000,2.388699e+000,1,0,2.709677e+000,0.000000e+000,2.338293e+000,,,,,,,1.211291e-005,,,,,,,,,,,,,,,,,,,,,
1607719087.056,,1.000000e+002,2.374696e+000,2.396851e+000,2,0,2.580645e-001,0.000000e+000,2.579843e+000,2.464714e+000,-6.130688e-001,-7.492001e-001,2.575771e+000,-5.020110e-001,-6.381423e-001,-4.532165e-006,-4.716821e-006,,,,,,,,,,,,,,,,,,,,
1607719087.056,,1.000000e+002,2.374696e+000,2.396851e+000,2,0,1.935484e+000,0.000000e+000,3.246968e+000,3.140994e+000,9.480650e-001,-7.292008e-002,3.365193e+000,1.172264e+000,1.512792e-001,3.490676e-005,3.505211e-005,,,,,,,,,,,,,,,,,,,,
1607719087.056,,1.000000e+002,2.374696e+000,2.396851e+000,2,0,3.612903e+000,0.000000e+000,8.094911e-001,7.020676e-001,-6.060072e-001,-2.511846e+000,7.896678e-001,-5.184070e-001,-2.424246e+000,-5.311277e-005,-5.307278e-005,,,,,,,,,,,,,,,,,,,,
1607719320.798,,1.000000e+002,2.254594e+000,2.292675e+000,1,0,1.161290e+000,0.000000e+000,2.191348e+000,,,,,,,2.114535e-005,,,,,,,,,,,,,,,,,,,,,
1607719320.798,,1.000000e+002,2.254594e+000,2.292675e+000,1,0,2.838710e+000,0.000000e+000,1.381094e+000,,,,,,,4.560570e-008,,,,,,,,,,,,,,,,,,,,,
1607719320.798,,1.000000e+002,2.245182e+000,2.285858e+000,2,0,3.870968e-001,0.000000e+000,2.198520e+000,2.034562e+000,-3.985346e-001,-6.078126e-001,1.917966e+000,-5.151306e-001,-7.244087e-001,3.268651e-006,2.815657e-006,,,,,,,,,,,,,,,,,,,,
1607719320.798,,1.000000e+002,2.245182e+000,2.285858e+000,2,0,2.064516e+000,0.000000e+000,2.647135e+000,2.502403e+000,9.761788e-001,-1.399710e-001,2.696302e+000,1.170077e+000,5.392742e-002,3.418310e-005,3.435359e-005,,,,,,,,,,,,,,,,,,,,
1607719320.798,,1.000000e+002,2.245182e+000,2.285858e+000,2,0,3.741935e+000,0.000000e+000,1.199359e-001,-2.113374e-002,-6.404865e-001,-2.663508e+000,1.158819e-001,-5.034709e-001,-2.526492e+000,-5.707359e-005,-5.691861e-005,,,,,,,,,,,,,,,,,,,,
1607721272.451,,1.000000e+002,2.182434e+000,2.236008e+000,1,0,1.290323e+000,0.000000e+000,3.893797e+000,,,,,,,2.459344e-005,,,,,,,,,,,,,,,,,,,,,
1607721272.451,,1.000000e+002,2.182434e+000,2.236008e+000,1,0,2.967742e+000,0.000000e+000,2.658274e+000,,,,,,,-1.328081e-005,,,,,,,,,,,,,,,,,,,,,
1607721272.451,,1.000000e+002,2.254143e+000,2.311934e+000,2,0,5.161290e-001,0.000000e+000,3.548028e+000,3.604562e+000,-2.311636e-001,-5.143523e-001,3.344379e+000,-4.913467e-001,-7.745354e-001,7.165712e-006,8.137518e-006,,,,,,,,,,,,,,,,,,,,
1607721272.451,,1.000000e+002,2.254143e+000,2.311934e+000,2,0,2.193548e+000,0.000000e+000,3.899138e+000,3.913329e+000,9.979662e-001,-2.055860e-001,4.012189e+000,1.096826e+000,-1.067257e-001,3.370484e-005,3.330092e-005,,,,,,,,,,,,,,,,,,,,
1607721272.451,,1.000000e+002,2.254143e+000,2.311934e+000,2,0,3.870968e+000,0.000000e+000,1.337606e+000,1.345388e+000,-6.496112e-001,-2.773527e+000,1.532939e+000,-4.620598e-001,-2.585975e+000,-5.933369e-005,-5.963801e-005,,,,,,,,,,,,,,,,,,,,
1607724096.465,,1.000000e+002,1.898787e+000,1.905195e+000,1,0,1.419355e+000,0.000000e+000,2.565652e+000,,,,,,,2.764548e-005,,,,,,,,,,,,,,,,,,,,,
1607724096.465,,1.000000e+002,1.898787e+000,1.905195e+000,1,0,3.096774e+000,0.000000e+000,7.986572e-001,,,,,,,-3.027522e-005,,,,,,,,,,,,,,,,,,,,,
1607724096.465,,1.000000e+002,1.991871e+000,1.995362e+000,2,0,6.451613e-001,0.000000e+000,2.534523e+000,2.501945e+000,-6.279640e-002,-4.645407e-001,2.177825e+000,-3.869165e-001,-7.886608e-001,1.501535e-005,1.597948e-005,,,,,,,,,,,,,,,,,,,,
1607724096.465,,1.000000e+002,1.991871e+000,1.995362e+000,2,0,2.322581e+000,0.000000e+000,2.554971e+000,2.484856e+000,9.646490e-001,-4.816306e-001,2.403323e+000,8.831165e-001,-5.631630e-001,2.993020e-005,2.962692e-005,,,,,,,,,,,,,,,,,,,,
1607724096.465,,1.000000e+002,1.991871e+000,1.995362e+000,2,0,4.000000e+000,0.000000e+000,4.364080e-002,-1.480125e-002,-4.904727e-001,-2.981287e+000,1.035052e-001,-3.721663e-001,-2.862981e+000,-5.909626e-005,-5.864666e-005,,,,,,,,,,,,,,,,,,,,