File: Project_codes/Almax_pressure_cell (upright) _Gasket+TAS100+Nujol+Sn+Ruby_background_25_Oe_cooling_AmbientPressure_3cmfromtop_Pressure_Reapplied.dc.raw
[Header]
TITLE,MPMS DC Measurement
BYAPP,MPMS Measurement,2.1,Raw with ABS
FILEOPENTIME, 1607868030.472000 12/13/2020, 3:00:30 PM

INFO, APPNAME, MPMS MultiVu Application, Revision 1.60,  Build 081

INFO, NAME, NiIrRu
INFO, WEIGHT, 1.000
INFO, AREA, 1.000
INFO, LENGTH, 1.000
INFO, SHAPE, 1
INFO, COMMENT,
INFO, SEQUENCE FILE: 12 12 2020 TAS 100 + Sn + Nujol.seq


INFO, BACKGROUND DATA FILE:, None


STARTUPAXIS,X,8,LINEAR,AUTO,0.000000,0.000000
STARTUPAXIS,Y1,10,LINEAR,AUTO,0.000000,0.000000


STARTUPGROUP,Longitudinal
FIELDGROUP,Longitudinal,1,3,4,5,6,8,9,10,11,12,13,14,15,16,17,18,19,20,21,22,23
FIELDGROUP,Transverse,1,3,4,5,6,8,9,24,25,26,27,28,29,30,31,32,33,34,35,36,37

PLOT_APPEARANCE,ALL,HORZ_GRID_ON,VERT_GRID_ON,MARKERS_ONLY

[Data]
Time,Comment,Field (Oe),Start Temperature (K),End Temperature (K),Scan,Rejected,Position (cm),Rot Position (deg),Long Voltage,Long Average Voltage,Long Detrended Voltage,Long Demeaned Voltage,Long Regression Fit,Long Detrended Fit,Long Demeaned Fit,Long Scaled Response,Long Avg. Scaled Response,Long Background Response,Long Response [w/ABS],Long Detrended Resp. [w/ABS],Long Fit [w/ABS],Long Detrended Fit [w/ABS],Trans Voltage,Trans Average Voltage,Trans Detrended Voltage,Trans Demeaned Voltage,Trans Regression Fit,Trans Detrended Fit,Trans Demeaned Fit,Trans Scaled Response,Trans Avg Scaled Response,Trans Background Response,Trans Response [w/ABS],Trans Detrended Resp. [w/ABS],Trans Fit [w/ABS],Trans Detrended Fit [w/ABS],
1607868030.462,,2.500000e+001,2.998971e+002,2.999323e+002,1,0,0.000000e+000,0.000000e+000,1.361868e+000,,,,,,,-7.251518e-006,,,,,,,,,,,,,,,,,,,,,
1607868030.462,,2.500000e+001,2.999323e+002,3.000025e+002,2,0,3.096774e+000,0.000000e+000,2.000610e+000,1.991379e+000,2.651669e-001,3.142782e-001,1.865642e+000,1.394307e-001,1.885420e-001,3.881163e-006,3.894264e-006,,,,,,,,,,,,,,,,,,,,
1607868251.263,,2.500000e+001,2.975645e+002,2.971177e+002,2,0,2.064516e+000,0.000000e+000,2.675059e+000,2.667124e+000,4.679467e-001,4.960330e-001,2.732706e+000,5.335285e-001,5.616148e-001,8.206807e-006,8.241808e-006,,,,,,,,,,,,,,,,,,,,
1607868307.603,,2.500000e+001,2.958335e+002,2.951278e+002,2,0,1.032258e+000,0.000000e+000,2.195163e+000,2.185321e+000,-9.255097e-002,-7.520580e-002,2.091841e+000,-1.860313e-001,-1.686862e-001,-3.246110e-006,-3.078403e-006,,,,,,,,,,,,,,,,,,,,
1607868336.993,,2.500000e+001,2.943920e+002,2.941981e+002,2,0,0.000000e+000,0.000000e+000,2.001984e+000,2.000305e+000,-3.052154e-001,-3.052154e-001,2.176035e+000,-1.294854e-001,-1.294854e-001,-7.205861e-006,-7.088627e-006,,,,,,,,,,,,,,,,,,,,
1607868367.603,,2.500000e+001,2.937607e+002,2.936600e+002,1,0,3.096774e+000,0.000000e+000,2.596933e+000,,,,,,,3.448862e-006,,,,,,,,,,,,,,,,,,,,,
1607868397.723,,2.500000e+001,2.925900e+002,2.922988e+002,1,0,2.064516e+000,0.000000e+000,2.858015e+000,,,,,,,8.387273e-006,,,,,,,,,,,,,,,,,,,,,
1607868467.403,,2.500000e+001,2.908850e+002,2.894285e+002,1,0,1.032258e+000,0.000000e+000,2.518959e+000,,,,,,,-3.073706e-006,,,,,,,,,,,,,,,,,,,,,
1607868498.243,,2.500000e+001,2.879631e+002,2.876494e+002,1,0,0.000000e+000,0.000000e+000,2.469062e+000,,,,,,,-6.916263e-006,,,,,,,,,,,,,,,,,,,,,
1607868498.243,,2.500000e+001,2.871440e+002,2.869441e+002,2,0,3.096774e+000,0.000000e+000,3.092241e+000,3.077287e+000,2.626008e-001,2.941642e-001,2.954233e+000,1.395466e-001,1.711099e-001,3.760375e-006,3.773839e-006,,,,,,,,,,,,,,,,,,,,
1607868528.823,,2.500000e+001,2.855524e+002,2.852442e+002,2,0,2.064516e+000,0.000000e+000,3.381094e+000,3.365759e+000,4.632878e-001,4.822357e-001,3.435542e+000,5.330715e-001,5.520194e-001,8.047966e-006,8.148025e-006,,,,,,,,,,,,,,,,,,,,
1607868557.413,,2.500000e+001,2.844336e+002,2.842454e+002,2,0,1.032258e+000,0.000000e+000,2.940261e+000,2.916610e+000,-7.188952e-002,-6.113601e-002,2.800487e+000,-1.880122e-001,-1.772587e-001,-2.553948e-006,-2.593020e-006,,,,,,,,,,,,,,,,,,,,
1607868586.963,,2.500000e+001,2.830363e+002,2.827260e+002,2,0,0.000000e+000,0.000000e+000,2.798810e+000,2.783017e+000,-3.102298e-001,-3.102298e-001,2.965093e+000,-1.281538e-001,-1.281538e-001,-7.137569e-006,-7.070681e-006,,,,,,,,,,,,,,,,,,,,
1607868615.543,,2.500000e+001,2.823314e+002,2.822001e+002,1,0,3.096774e+000,0.000000e+000,3.430381e+000,,,,,,,3.550304e-006,,,,,,,,,,,,,,,,,,,,,
1607868645.153,,2.500000e+001,2.809481e+002,2.805283e+002,1,0,2.064516e+000,0.000000e+000,3.726558e+000,,,,,,,8.291070e-006,,,,,,,,,,,,,,,,,,,,,
1607868673.663,,2.500000e+001,2.798138e+002,2.795941e+002,1,0,1.032258e+000,0.000000e+000,3.248341e+000,,,,,,,-3.220412e-006,,,,,,,,,,,,,,,,,,,,,
1607868703.243,,2.500000e+001,2.783888e+002,2.782164e+002,1,0,0.000000e+000,0.000000e+000,3.168689e+000,,,,,,,-7.245588e-006,,,,,,,,,,,,,,,,,,,,,
1607868703.243,,2.500000e+001,2.778649e+002,2.775664e+002,2,0,3.096774e+000,0.000000e+000,3.817960e+000,3.788281e+000,2.518677e-001,2.808414e-001,3.677054e+000,1.406404e-001,1.696141e-001,3.607522e-006,3.536232e-006,,,,,,,,,,,,,,,,,,,,
1607868732.233,,2.500000e+001,2.764090e+002,2.759739e+002,2,0,2.064516e+000,0.000000e+000,4.129091e+000,4.101396e+000,4.590931e-001,4.805877e-001,4.166707e+000,5.244040e-001,5.458987e-001,8.054776e-006,8.064068e-006,,,,,,,,,,,,,,,,,,,,
1607868763.133,,2.500000e+001,2.752324e+002,2.749618e+002,2,0,1.032258e+000,0.000000e+000,3.610590e+000,3.605020e+000,-8.544528e-002,-8.116627e-002,3.499706e+000,-1.907595e-001,-1.864805e-001,-2.967136e-006,-2.779649e-006,,,,,,,,,,,,,,,,,,,,
1607868840.733,,2.500000e+001,2.719435e+002,2.716654e+002,2,0,0.000000e+000,0.000000e+000,3.375601e+000,3.312734e+000,-3.019629e-001,-3.019629e-001,3.486775e+000,-1.279211e-001,-1.279211e-001,-7.233321e-006,-7.188326e-006,,,,,,,,,,,,,,,,,,,,
1607868869.743,,2.500000e+001,2.712246e+002,2.711679e+002,1,0,3.096774e+000,0.000000e+000,4.069428e+000,,,,,,,3.657391e-006,,,,,,,,,,,,,,,,,,,,,
1607868898.223,,2.500000e+001,2.700941e+002,2.700168e+002,1,0,2.064516e+000,0.000000e+000,4.408637e+000,,,,,,,8.139308e-006,,,,,,,,,,,,,,,,,,,,,
1607868927.233,,2.500000e+001,2.691130e+002,2.690712e+002,1,0,1.032258e+000,0.000000e+000,3.981231e+000,,,,,,,-2.631001e-006,,,,,,,,,,,,,,,,,,,,,
1607868955.843,,2.500000e+001,2.679456e+002,2.680079e+002,1,0,0.000000e+000,0.000000e+000,3.850461e+000,,,,,,,-7.087743e-006,,,,,,,,,,,,,,,,,,,,,
1607868955.843,,2.500000e+001,2.676761e+002,2.672421e+002,2,0,3.096774e+000,0.000000e+000,4.499886e+000,4.472648e+000,2.648144e-001,2.871923e-001,4.349173e+000,1.413394e-001,1.637173e-001,3.764813e-006,3.759546e-006,,,,,,,,,,,,,,,,,,,,
1607869038.494,,2.500000e+001,2.649385e+002,2.644330e+002,2,0,2.064516e+000,0.000000e+000,5.054093e+000,5.027085e+000,4.460319e-001,4.511147e-001,5.095832e+000,5.147794e-001,5.198622e-001,7.937473e-006,7.807088e-006,,,,,,,,,,,,,,,,,,,,
1607869067.754,,2.500000e+001,2.632881e+002,2.631882e+002,2,0,1.032258e+000,0.000000e+000,4.657664e+000,4.617304e+000,-8.152335e-002,-7.040262e-002,4.514919e+000,-1.839084e-001,-1.727877e-001,-2.721048e-006,-2.790912e-006,,,,,,,,,,,,,,,,,,,,
1607869096.844,,2.500000e+001,2.623127e+002,2.622333e+002,2,0,0.000000e+000,0.000000e+000,4.529335e+000,4.504616e+000,-2.984047e-001,-2.984047e-001,4.674749e+000,-1.282711e-001,-1.282711e-001,-6.808186e-006,-6.859729e-006,,,,,,,,,,,,,,,,,,,,
1607869126.094,,2.500000e+001,2.618836e+002,2.618177e+002,1,0,3.096774e+000,0.000000e+000,5.148394e+000,,,,,,,3.821580e-006,,,,,,,,,,,,,,,,,,,,,
1607869156.624,,2.500000e+001,2.610102e+002,2.608010e+002,1,0,2.064516e+000,0.000000e+000,5.420615e+000,,,,,,,8.075847e-006,,,,,,,,,,,,,,,,,,,,,
1607869240.284,,2.500000e+001,2.594039e+002,2.574674e+002,1,0,1.032258e+000,0.000000e+000,5.210651e+000,,,,,,,-2.844477e-006,,,,,,,,,,,,,,,,,,,,,
1607869269.994,,2.500000e+001,2.563398e+002,2.560564e+002,1,0,0.000000e+000,0.000000e+000,5.133287e+000,,,,,,,-7.037161e-006,,,,,,,,,,,,,,,,,,,,,
1607869269.994,,2.500000e+001,2.556983e+002,2.557234e+002,2,0,3.096774e+000,0.000000e+000,5.769894e+000,5.736401e+000,2.452663e-001,2.739997e-001,5.629601e+000,1.384672e-001,1.672006e-001,3.517678e-006,3.395602e-006,,,,,,,,,,,,,,,,,,,,
1607869299.804,,2.500000e+001,2.545555e+002,2.543133e+002,2,0,2.064516e+000,0.000000e+000,6.089876e+000,6.073930e+000,4.788586e-001,4.944720e-001,6.128726e+000,5.336543e-001,5.492678e-001,8.243500e-006,8.457733e-006,,,,,,,,,,,,,,,,,,,,
1607869328.604,,2.500000e+001,2.534108e+002,2.532692e+002,2,0,1.032258e+000,0.000000e+000,5.654383e+000,5.624857e+000,-8.470485e-002,-7.494211e-002,5.524324e+000,-1.852374e-001,-1.754746e-001,-2.945220e-006,-2.850647e-006,,,,,,,,,,,,,,,,,,,,
1607869358.334,,2.500000e+001,2.522462e+002,2.520146e+002,2,0,0.000000e+000,0.000000e+000,5.572290e+000,5.542077e+000,-3.068042e-001,-3.068042e-001,5.718098e+000,-1.307836e-001,-1.307836e-001,-7.018825e-006,-7.116541e-006,,,,,,,,,,,,,,,,,,,,
1607869387.724,,2.500000e+001,2.516498e+002,2.512255e+002,1,0,3.096774e+000,0.000000e+000,6.223087e+000,,,,,,,3.689929e-006,,,,,,,,,,,,,,,,,,,,,
1607869417.174,,2.500000e+001,2.503695e+002,2.504235e+002,1,0,2.064516e+000,0.000000e+000,6.565042e+000,,,,,,,8.397677e-006,,,,,,,,,,,,,,,,,,,,,
1607869494.644,,2.500000e+001,2.488887e+002,2.472558e+002,1,0,1.032258e+000,0.000000e+000,6.259251e+000,,,,,,,-2.964662e-006,,,,,,,,,,,,,,,,,,,,,
1607869524.054,,2.500000e+001,2.457143e+002,2.455237e+002,1,0,0.000000e+000,0.000000e+000,6.162966e+000,,,,,,,-7.118186e-006,,,,,,,,,,,,,,,,,,,,,
1607869524.054,,2.500000e+001,2.450457e+002,2.447529e+002,2,0,3.096774e+000,0.000000e+000,6.825361e+000,6.787595e+000,2.582873e-001,2.828612e-001,6.662544e+000,1.332367e-001,1.578107e-001,3.717054e-006,3.657784e-006,,,,,,,,,,,,,,,,,,,,
1607869553.174,,2.500000e+001,2.438448e+002,2.436004e+002,2,0,2.064516e+000,0.000000e+000,7.172503e+000,7.154803e+000,5.037010e-001,5.157318e-001,7.195849e+000,5.447466e-001,5.567775e-001,8.797419e-006,8.955874e-006,,,,,,,,,,,,,,,,,,,,
1607869582.374,,2.500000e+001,2.426391e+002,2.424366e+002,2,0,1.032258e+000,0.000000e+000,6.693065e+000,6.667659e+000,-8.156294e-002,-5.879259e-002,6.568141e+000,-1.810803e-001,-1.583099e-001,-3.132387e-006,-2.930363e-006,,,,,,,,,,,,,,,,,,,,
1607869612.794,,2.500000e+001,2.415460e+002,2.410449e+002,2,0,0.000000e+000,0.000000e+000,6.626383e+000,6.582131e+000,-3.047056e-001,-3.047056e-001,6.753107e+000,-1.337299e-001,-1.337299e-001,-7.248978e-006,-7.207374e-006,,,,,,,,,,,,,,,,,,,,
1607869642.034,,2.500000e+001,2.407564e+002,2.405128e+002,1,0,3.096774e+000,0.000000e+000,7.311055e+000,,,,,,,3.649591e-006,,,,,,,,,,,,,,,,,,,,,
1607869671.284,,2.500000e+001,2.396203e+002,2.395709e+002,1,0,2.064516e+000,0.000000e+000,7.590296e+000,,,,,,,8.116767e-006,,,,,,,,,,,,,,,,,,,,,
1607869752.785,,2.500000e+001,2.383431e+002,2.366512e+002,1,0,1.032258e+000,0.000000e+000,7.344167e+000,,,,,,,-2.703076e-006,,,,,,,,,,,,,,,,,,,,,
1607869781.295,,2.500000e+001,2.352372e+002,2.350577e+002,1,0,0.000000e+000,0.000000e+000,7.240253e+000,,,,,,,-7.131428e-006,,,,,,,,,,,,,,,,,,,,,
1607869781.295,,2.500000e+001,2.346838e+002,2.346102e+002,2,0,3.096774e+000,0.000000e+000,7.871519e+000,7.842527e+000,2.370914e-001,2.716217e-001,7.731613e+000,1.261772e-001,1.607075e-001,3.226247e-006,3.308043e-006,,,,,,,,,,,,,,,,,,,,
1607869810.495,,2.500000e+001,2.335434e+002,2.335174e+002,2,0,2.064516e+000,0.000000e+000,8.196383e+000,8.183032e+000,4.709308e-001,4.761195e-001,8.251576e+000,5.394752e-001,5.446639e-001,8.151459e-006,8.300136e-006,,,,,,,,,,,,,,,,,,,,
1607869841.025,,2.500000e+001,2.326341e+002,2.323557e+002,2,0,1.032258e+000,0.000000e+000,7.785306e+000,7.742199e+000,-7.960504e-002,-7.018757e-002,7.642161e+000,-1.796426e-001,-1.702251e-001,-2.739165e-006,-2.750079e-006,,,,,,,,,,,,,,,,,,,,
1607869871.145,,2.500000e+001,2.314682e+002,2.308209e+002,2,0,0.000000e+000,0.000000e+000,7.673762e+000,7.645380e+000,-3.093538e-001,-3.093538e-001,7.818662e+000,-1.360722e-001,-1.360722e-001,-7.039314e-006,-7.075112e-006,,,,,,,,,,,,,,,,,,,,
1607869902.075,,2.500000e+001,2.309226e+002,2.302329e+002,1,0,3.096774e+000,0.000000e+000,8.301213e+000,,,,,,,3.258494e-006,,,,,,,,,,,,,,,,,,,,,
1607869982.705,,2.500000e+001,2.292814e+002,2.276436e+002,1,0,2.064516e+000,0.000000e+000,8.847334e+000,,,,,,,8.190866e-006,,,,,,,,,,,,,,,,,,,,,
1607870012.055,,2.500000e+001,2.262291e+002,2.262584e+002,1,0,1.032258e+000,0.000000e+000,8.456702e+000,,,,,,,-2.775429e-006,,,,,,,,,,,,,,,,,,,,,
1607870041.575,,2.500000e+001,2.253007e+002,2.250638e+002,1,0,0.000000e+000,0.000000e+000,8.347296e+000,,,,,,,-6.940041e-006,,,,,,,,,,,,,,,,,,,,,
1607870041.575,,2.500000e+001,2.248226e+002,2.245337e+002,2,0,3.096774e+000,0.000000e+000,8.962539e+000,8.932249e+000,2.528085e-001,2.570629e-001,8.806657e+000,1.272163e-001,1.314707e-001,3.581110e-006,3.441659e-006,,,,,,,,,,,,,,,,,,,,
1607870070.845,,2.500000e+001,2.235573e+002,2.234477e+002,2,0,2.064516e+000,0.000000e+000,9.313344e+000,9.293049e+000,5.016398e-001,5.108700e-001,9.349931e+000,5.585217e-001,5.677519e-001,8.621166e-006,8.908508e-006,,,,,,,,,,,,,,,,,,,,
1607870100.845,,2.500000e+001,2.223581e+002,2.223157e+002,2,0,1.032258e+000,0.000000e+000,8.882734e+000,8.845579e+000,-8.244248e-002,-7.592106e-002,8.753659e+000,-1.743624e-001,-1.678410e-001,-2.709072e-006,-2.780507e-006,,,,,,,,,,,,,,,,,,,,
1607870174.815,,2.500000e+001,2.196113e+002,2.193449e+002,2,0,0.000000e+000,0.000000e+000,9.018082e+000,8.981995e+000,-3.136806e-001,-3.136806e-001,9.156713e+000,-1.389618e-001,-1.389618e-001,-7.249560e-006,-7.313225e-006,,,,,,,,,,,,,,,,,,,,
1607870248.115,,2.500000e+001,2.172643e+002,2.170800e+002,1,0,3.096774e+000,0.000000e+000,1.963378e+000,,,,,,,2.875808e-006,,,,,,,,,,,,,,,,,,,,,
1607870278.005,,2.500000e+001,2.161007e+002,2.157408e+002,1,0,2.064516e+000,0.000000e+000,2.044251e+000,,,,,,,8.547475e-006,,,,,,,,,,,,,,,,,,,,,
1607870307.335,,2.500000e+001,2.148000e+002,2.147473e+002,1,0,1.032258e+000,0.000000e+000,1.958038e+000,,,,,,,-2.688728e-006,,,,,,,,,,,,,,,,,,,,,
1607870336.715,,2.500000e+001,2.136715e+002,2.136715e+002,1,0,0.000000e+000,0.000000e+000,1.932555e+000,,,,,,,-7.244671e-006,,,,,,,,,,,,,,,,,,,,,
1607870336.715,,2.500000e+001,2.131853e+002,2.128869e+002,2,0,3.096774e+000,0.000000e+000,2.055696e+000,2.049058e+000,4.731844e-002,4.719782e-002,2.025405e+000,2.366589e-002,2.354527e-002,3.271562e-006,3.104273e-006,,,,,,,,,,,,,,,,,,,,
1607870365.965,,2.500000e+001,2.120908e+002,2.117271e+002,2,0,2.064516e+000,0.000000e+000,2.127108e+000,2.121462e+000,9.779641e-002,9.839630e-002,2.136307e+000,1.126411e-001,1.132410e-001,8.577539e-006,8.651783e-006,,,,,,,,,,,,,,,,,,,,
1607870424.276,,2.500000e+001,2.097635e+002,2.096169e+002,2,0,1.032258e+000,0.000000e+000,-2.355993e+000,-2.376593e+000,-3.704426e-002,-3.652501e-002,-2.426544e+000,-8.699605e-002,-8.647680e-002,-2.470319e-006,-2.556997e-006,,,,,,,,,,,,,,,,,,,,
1607870453.056,,2.500000e+001,2.086087e+002,2.086087e+002,2,0,0.000000e+000,0.000000e+000,5.116045e+000,5.100557e+000,-3.233166e-001,-3.233166e-001,4.533812e+000,-8.900619e-001,-8.900619e-001,3.140954e-005,2.454923e-005,,,,,,,,,,,,,,,,,,,,
1607870482.476,,2.500000e+001,2.080958e+002,2.080669e+002,1,0,3.096774e+000,0.000000e+000,-2.094911e+000,,,,,,,3.054927e-006,,,,,,,,,,,,,,,,,,,,,
1607870513.756,,2.500000e+001,2.071921e+002,2.067311e+002,1,0,2.064516e+000,0.000000e+000,-2.012512e+000,,,,,,,8.529212e-006,,,,,,,,,,,,,,,,,,,,,
1607870543.356,,2.500000e+001,2.058591e+002,2.056253e+002,1,0,1.032258e+000,0.000000e+000,5.178149e+000,,,,,,,-2.218178e-006,,,,,,,,,,,,,,,,,,,,,
1607870572.406,,2.500000e+001,2.047030e+002,2.043006e+002,1,0,0.000000e+000,0.000000e+000,-2.483253e+000,,,,,,,-6.900533e-006,,,,,,,,,,,,,,,,,,,,,
1607870572.406,,2.500000e+001,2.040068e+002,2.040464e+002,2,0,3.096774e+000,0.000000e+000,-2.223392e+000,-2.225528e+000,1.144701e-001,9.575844e-002,-2.283401e+000,5.659705e-002,3.788543e-002,2.809800e-006,2.786779e-006,,,,,,,,,,,,,,,,,,,,
1607870629.526,,2.500000e+001,2.018757e+002,2.016817e+002,2,0,2.064516e+000,0.000000e+000,5.466087e+000,1.689860e+000,3.380592e-001,2.731471e-001,1.544212e+000,1.924111e-001,1.274990e-001,1.735584e-005,1.303787e-005,,,,,,,,,,,,,,,,,,,,
1607870658.746,,2.500000e+001,2.011057e+002,2.006557e+002,2,0,1.032258e+000,0.000000e+000,-2.313878e+000,1.443351e+000,-3.438813e-002,-3.826475e-002,1.391797e+000,-8.594161e-002,-8.981824e-002,-2.328045e-006,-2.344896e-006,,,,,,,,,,,,,,,,,,,,
1607870687.856,,2.500000e+001,1.998186e+002,1.995107e+002,2,0,0.000000e+000,0.000000e+000,-2.399786e+000,-2.407492e+000,-1.618636e-001,-1.618636e-001,-2.317217e+000,-7.158875e-002,-7.158875e-002,-7.192997e-006,-7.118237e-006,,,,,,,,,,,,,,,,,,,,
1607870717.116,,2.500000e+001,1.990753e+002,1.989469e+002,1,0,3.096774e+000,0.000000e+000,-2.121920e+000,,,,,,,2.716188e-006,,,,,,,,,,,,,,,,,,,,,
1607870789.206,,2.500000e+001,1.977688e+002,1.961996e+002,1,0,2.064516e+000,0.000000e+000,-2.041962e+000,,,,,,,8.601608e-006,,,,,,,,,,,,,,,,,,,,,
1607870818.506,,2.500000e+001,1.948829e+002,1.947453e+002,1,0,1.032258e+000,0.000000e+000,-2.248264e+000,,,,,,,-2.380853e-006,,,,,,,,,,,,,,,,,,,,,
1607870846.946,,2.500000e+001,1.936192e+002,1.934333e+002,1,0,0.000000e+000,0.000000e+000,-2.313573e+000,,,,,,,-7.320356e-006,,,,,,,,,,,,,,,,,,,,,
1607870846.946,,2.500000e+001,1.931374e+002,1.928672e+002,2,0,3.096774e+000,0.000000e+000,-2.025025e+000,-2.035477e+000,1.107283e-001,9.765267e-002,-2.092603e+000,5.360201e-002,4.052639e-002,2.591813e-006,2.682507e-006,,,,,,,,,,,,,,,,,,,,
1607870920.016,,2.500000e+001,1.900713e+002,1.901265e+002,2,0,2.064516e+000,0.000000e+000,-3.539025e+000,-3.559854e+000,4.994405e-001,4.815197e-001,-3.481365e+000,5.779291e-001,5.600083e-001,8.840812e-006,8.859592e-006,,,,,,,,,,,,,,,,,,,,
1607870948.456,,2.500000e+001,1.890317e+002,1.887591e+002,2,0,1.032258e+000,0.000000e+000,-4.003357e+000,-4.025559e+000,-6.771662e-002,-7.780313e-002,-4.124063e+000,-1.662212e-001,-1.763077e-001,-2.276691e-006,-2.296874e-006,,,,,,,,,,,,,,,,,,,,
1607870977.506,,2.500000e+001,1.878819e+002,1.877101e+002,2,0,0.000000e+000,0.000000e+000,-4.180057e+000,-4.198825e+000,-3.335586e-001,-3.335586e-001,-4.012182e+000,-1.469159e-001,-1.469159e-001,-7.219714e-006,-7.226030e-006,,,,,,,,,,,,,,,,,,,,
1607871006.656,,2.500000e+001,1.871430e+002,1.869659e+002,1,0,3.096774e+000,0.000000e+000,-3.626459e+000,,,,,,,2.515080e-006,,,,,,,,,,,,,,,,,,,,,
1607871036.036,,2.500000e+001,1.861181e+002,1.857317e+002,1,0,2.064516e+000,0.000000e+000,-3.238270e+000,,,,,,,8.764342e-006,,,,,,,,,,,,,,,,,,,,,
1607871065.196,,2.500000e+001,1.848917e+002,1.848656e+002,1,0,1.032258e+000,0.000000e+000,-3.694209e+000,,,,,,,-2.131914e-006,,,,,,,,,,,,,,,,,,,,,
1607871094.506,,2.500000e+001,1.838554e+002,1.836778e+002,1,0,0.000000e+000,0.000000e+000,-3.846647e+000,,,,,,,-7.236929e-006,,,,,,,,,,,,,,,,,,,,,
1607871094.506,,2.500000e+001,1.831281e+002,1.828112e+002,2,0,3.096774e+000,0.000000e+000,-3.284504e+000,-3.311131e+000,2.122347e-001,1.740298e-001,-3.423430e+000,9.993596e-002,6.173110e-002,2.454908e-006,2.446934e-006,,,,,,,,,,,,,,,,,,,,
1607871198.057,,2.500000e+001,1.789984e+002,1.790168e+002,2,0,2.064516e+000,0.000000e+000,-1.765164e+000,-2.602426e-001,6.603941e-001,-2.379039e-001,-3.749926e-001,5.456442e-001,-3.526539e-001,-1.088578e-004,1.122521e-004,,,,,,,,,,,,,,,,,,,,
1607871300.607,,2.500000e+001,1.750119e+002,1.747977e+002,2,0,1.032258e+000,0.000000e+000,-2.996414e+000,-3.012436e+000,-5.960143e-002,-7.764006e-002,-3.114294e+000,-1.614593e-001,-1.794980e-001,-2.038621e-006,-2.049725e-006,,,,,,,,,,,,,,,,,,,,
1607871329.617,,2.500000e+001,1.738472e+002,1.736068e+002,2,0,0.000000e+000,0.000000e+000,-3.155413e+000,-3.189517e+000,-3.430891e-001,-3.430891e-001,-2.996638e+000,-1.502104e-001,-1.502104e-001,-7.321862e-006,-7.391478e-006,,,,,,,,,,,,,,,,,,,,
1607871358.957,,2.500000e+001,1.732604e+002,1.730072e+002,1,0,3.096774e+000,0.000000e+000,-2.610208e+000,,,,,,,2.137247e-006,,,,,,,,,,,,,,,,,,,,,
1607871388.387,,2.500000e+001,1.720667e+002,1.718112e+002,1,0,2.064516e+000,0.000000e+000,-2.216526e+000,,,,,,,8.851086e-006,,,,,,,,,,,,,,,,,,,,,
1607871418.227,,2.500000e+001,1.712064e+002,1.705246e+002,1,0,1.032258e+000,0.000000e+000,-2.642863e+000,,,,,,,-2.107023e-006,,,,,,,,,,,,,,,,,,,,,
1607871447.497,,2.500000e+001,1.697843e+002,1.694192e+002,1,0,0.000000e+000,0.000000e+000,-2.776990e+000,,,,,,,-7.283932e-006,,,,,,,,,,,,,,,,,,,,,
1607871447.497,,2.500000e+001,1.691215e+002,1.689566e+002,2,0,3.096774e+000,0.000000e+000,-2.238193e+000,-2.258564e+000,2.067956e-001,1.520176e-001,-2.375324e+000,9.003611e-002,3.525805e-002,2.205285e-006,2.266257e-006,,,,,,,,,,,,,,,,,,,,
1607871521.747,,2.500000e+001,1.660985e+002,1.659551e+002,2,0,2.064516e+000,0.000000e+000,-1.608911e+000,-1.640345e+000,5.031321e-001,4.715521e-001,-1.549130e+000,5.943471e-001,5.627671e-001,8.907140e-006,8.927713e-006,,,,,,,,,,,,,,,,,,,,
1607871579.857,,2.500000e+001,1.637030e+002,1.635067e+002,2,0,1.032258e+000,0.000000e+000,-1.923552e+000,-1.962081e+000,-6.882243e-002,-8.521318e-002,-2.048917e+000,-1.556584e-001,-1.720492e-001,-2.062101e-006,-2.266006e-006,,,,,,,,,,,,,,,,,,,,
1607871608.997,,2.500000e+001,1.625426e+002,1.621863e+002,2,0,0.000000e+000,0.000000e+000,-2.067292e+000,-2.097581e+000,-3.389002e-001,-3.389002e-001,-1.911291e+000,-1.526095e-001,-1.526095e-001,-7.279443e-006,-7.282011e-006,,,,,,,,,,,,,,,,,,,,
1607871638.257,,2.500000e+001,1.618822e+002,1.616925e+002,1,0,3.096774e+000,0.000000e+000,-1.514763e+000,,,,,,,2.140616e-006,,,,,,,,,,,,,,,,,,,,,
1607871666.897,,2.500000e+001,1.607486e+002,1.605989e+002,1,0,2.064516e+000,0.000000e+000,-1.057450e+000,,,,,,,9.043688e-006,,,,,,,,,,,,,,,,,,,,,
1607871695.157,,2.500000e+001,1.594800e+002,1.591512e+002,1,0,1.032258e+000,0.000000e+000,-1.481498e+000,,,,,,,-1.999106e-006,,,,,,,,,,,,,,,,,,,,,
1607871724.527,,2.500000e+001,1.583273e+002,1.582256e+002,1,0,0.000000e+000,0.000000e+000,-1.634699e+000,,,,,,,-7.588733e-006,,,,,,,,,,,,,,,,,,,,,
1607871724.527,,2.500000e+001,1.577088e+002,1.574924e+002,2,0,3.096774e+000,0.000000e+000,-1.065232e+000,-1.103685e+000,1.947359e-001,1.415231e-001,-1.216116e+000,8.230494e-002,2.909219e-002,2.176024e-006,2.048762e-006,,,,,,,,,,,,,,,,,,,,
1607871753.747,,2.500000e+001,1.566658e+002,1.560784e+002,2,0,2.064516e+000,0.000000e+000,-6.309606e-001,-6.601053e-001,4.974500e-001,4.565865e-001,-5.593093e-001,5.982460e-001,5.573825e-001,8.814572e-006,8.811643e-006,,,,,,,,,,,,,,,,,,,,
1607871783.047,,2.500000e+001,1.553359e+002,1.551023e+002,2,0,1.032258e+000,0.000000e+000,-1.039597e+000,-1.067216e+000,-4.541453e-002,-6.675208e-002,-1.175281e+000,-1.534797e-001,-1.748172e-001,-1.722659e-006,-1.729539e-006,,,,,,,,,,,,,,,,,,,,
1607871811.447,,2.500000e+001,1.541793e+002,1.540365e+002,2,0,0.000000e+000,0.000000e+000,-1.217212e+000,-1.243992e+000,-3.508589e-001,-3.508589e-001,-1.047951e+000,-1.548182e-001,-1.548182e-001,-7.451537e-006,-7.442160e-006,,,,,,,,,,,,,,,,,,,,
1607871840.008,,2.500000e+001,1.537699e+002,1.534402e+002,1,0,3.096774e+000,0.000000e+000,-6.767377e-001,,,,,,,1.897035e-006,,,,,,,,,,,,,,,,,,,,,
1607871869.038,,2.500000e+001,1.524862e+002,1.521212e+002,1,0,2.064516e+000,0.000000e+000,-1.828031e-001,,,,,,,9.096228e-006,,,,,,,,,,,,,,,,,,,,,
1607871898.458,,2.500000e+001,1.512226e+002,1.509386e+002,1,0,1.032258e+000,0.000000e+000,-6.195163e-001,,,,,,,-1.884138e-006,,,,,,,,,,,,,,,,,,,,,
1607871926.778,,2.500000e+001,1.500400e+002,1.496904e+002,1,0,0.000000e+000,0.000000e+000,-7.771420e-001,,,,,,,-7.340778e-006,,,,,,,,,,,,,,,,,,,,,
1607871926.778,,2.500000e+001,1.494510e+002,1.493424e+002,2,0,3.096774e+000,0.000000e+000,-2.468910e-001,-2.704662e-001,1.927263e-001,1.304449e-001,-3.891549e-001,7.403756e-002,1.175612e-002,1.890901e-006,2.002698e-006,,,,,,,,,,,,,,,,,,,,
1607871956.038,,2.500000e+001,1.482516e+002,1.478417e+002,2,0,2.064516e+000,0.000000e+000,2.102693e-001,1.740291e-001,4.967674e-001,4.555563e-001,2.722691e-001,5.950073e-001,5.537963e-001,8.934200e-006,8.822915e-006,,,,,,,,,,,,,,,,,,,,
1607871984.838,,2.500000e+001,1.470494e+002,1.469230e+002,2,0,1.032258e+000,0.000000e+000,-1.844816e-001,-2.182040e-001,-5.030435e-002,-6.940241e-002,-3.138542e-001,-1.459546e-001,-1.650526e-001,-1.887016e-006,-1.847134e-006,,,,,,,,,,,,,,,,,,,,
1607872014.178,,2.500000e+001,1.460982e+002,1.456250e+002,2,0,0.000000e+000,0.000000e+000,-3.218128e-001,-3.598077e-001,-3.510133e-001,-3.510133e-001,-1.638619e-001,-1.550675e-001,-1.550675e-001,-7.252666e-006,-7.405557e-006,,,,,,,,,,,,,,,,,,,,
1607872043.038,,2.500000e+001,1.453111e+002,1.452287e+002,1,0,3.096774e+000,0.000000e+000,2.012665e-001,,,,,,,1.624117e-006,,,,,,,,,,,,,,,,,,,,,
1607872071.938,,2.500000e+001,1.441981e+002,1.439466e+002,1,0,2.064516e+000,0.000000e+000,6.770428e-001,,,,,,,9.014992e-006,,,,,,,,,,,,,,,,,,,,,
1607872101.108,,2.500000e+001,1.430119e+002,1.426289e+002,1,0,1.032258e+000,0.000000e+000,2.473488e-001,,,,,,,-1.987009e-006,,,,,,,,,,,,,,,,,,,,,
1607872130.368,,2.500000e+001,1.418057e+002,1.416209e+002,1,0,0.000000e+000,0.000000e+000,9.246967e-002,,,,,,,-7.425855e-006,,,,,,,,,,,,,,,,,,,,,
1607872130.368,,2.500000e+001,1.412136e+002,1.409368e+002,2,0,3.096774e+000,0.000000e+000,6.230258e-001,5.922027e-001,1.812226e-001,1.175497e-001,4.837301e-001,7.275002e-002,9.077162e-003,1.701837e-006,1.728781e-006,,,,,,,,,,,,,,,,,,,,
1607872160.328,,2.500000e+001,1.399778e+002,1.396673e+002,2,0,2.064516e+000,0.000000e+000,1.110552e+000,1.079881e+000,5.098172e-001,4.672482e-001,1.181967e+000,6.119031e-001,5.693341e-001,8.925468e-006,9.061895e-006,,,,,,,,,,,,,,,,,,,,
1607872227.678,,2.500000e+001,1.371503e+002,1.368660e+002,2,0,1.032258e+000,0.000000e+000,9.242390e-001,8.901350e-001,-4.121202e-002,-6.572157e-002,7.855237e-001,-1.458234e-001,-1.703329e-001,-1.614146e-006,-1.624314e-006,,,,,,,,,,,,,,,,,,,,
1607872257.338,,2.500000e+001,1.357507e+002,1.354429e+002,2,0,0.000000e+000,0.000000e+000,7.515068e-001,7.236592e-001,-3.497037e-001,-3.497037e-001,9.133349e-001,-1.600279e-001,-1.600279e-001,-7.288516e-006,-7.306930e-006,,,,,,,,,,,,,,,,,,,,
1607872286.148,,2.500000e+001,1.351615e+002,1.346843e+002,1,0,3.096774e+000,0.000000e+000,1.274281e+000,,,,,,,1.637200e-006,,,,,,,,,,,,,,,,,,,,,
1607872315.618,,2.500000e+001,1.339265e+002,1.335700e+002,1,0,2.064516e+000,0.000000e+000,1.790341e+000,,,,,,,9.226500e-006,,,,,,,,,,,,,,,,,,,,,
1607872344.348,,2.500000e+001,1.328133e+002,1.325802e+002,1,0,1.032258e+000,0.000000e+000,1.392538e+000,,,,,,,-1.674249e-006,,,,,,,,,,,,,,,,,,,,,
1607872374.848,,2.500000e+001,1.315424e+002,1.312146e+002,1,0,0.000000e+000,0.000000e+000,1.257496e+000,,,,,,,-7.421972e-006,,,,,,,,,,,,,,,,,,,,,
1607872374.848,,2.500000e+001,1.309493e+002,1.305904e+002,2,0,3.096774e+000,0.000000e+000,1.791409e+000,1.755627e+000,1.798565e-001,1.106917e-001,1.643389e+000,6.761836e-002,-1.546502e-003,1.688517e-006,1.680990e-006,,,,,,,,,,,,,,,,,,,,
1607872443.848,,2.500000e+001,1.281284e+002,1.277707e+002,2,0,2.064516e+000,0.000000e+000,2.507973e+000,2.478065e+000,5.117542e-001,4.645774e-001,2.585375e+000,6.190642e-001,5.718875e-001,8.945979e-006,9.095424e-006,,,,,,,,,,,,,,,,,,,,
1607872473.328,,2.500000e+001,1.266887e+002,1.264656e+002,2,0,1.032258e+000,0.000000e+000,2.125734e+000,2.089876e+000,-4.651584e-002,-7.334876e-002,1.995512e+000,-1.408790e-001,-1.677120e-001,-1.677436e-006,-1.703156e-006,,,,,,,,,,,,,,,,,,,,
1607872502.208,,2.500000e+001,1.255647e+002,1.253922e+002,2,0,0.000000e+000,0.000000e+000,1.977569e+000,1.941711e+000,-3.552240e-001,-3.552240e-001,2.135998e+000,-1.609371e-001,-1.609371e-001,-7.431830e-006,-7.407954e-006,,,,,,,,,,,,,,,,,,,,
1607872531.388,,2.500000e+001,1.249800e+002,1.246353e+002,1,0,3.096774e+000,0.000000e+000,2.494240e+000,,,,,,,1.441302e-006,,,,,,,,,,,,,,,,,,,,,
1607872561.119,,2.500000e+001,1.239083e+002,1.236026e+002,1,0,2.064516e+000,0.000000e+000,2.992447e+000,,,,,,,9.161267e-006,,,,,,,,,,,,,,,,,,,,,
1607872591.179,,2.500000e+001,1.225436e+002,1.221217e+002,1,0,1.032258e+000,0.000000e+000,2.577707e+000,,,,,,,-1.586013e-006,,,,,,,,,,,,,,,,,,,,,
1607872658.129,,2.500000e+001,1.211535e+002,1.197376e+002,1,0,0.000000e+000,0.000000e+000,2.353552e+000,,,,,,,-7.486982e-006,,,,,,,,,,,,,,,,,,,,,
1607872658.129,,2.500000e+001,1.191735e+002,1.187982e+002,2,0,3.096774e+000,0.000000e+000,2.900588e+000,2.852598e+000,1.621898e-001,9.708834e-002,2.748757e+000,5.834900e-002,-6.752491e-003,1.357112e-006,1.387067e-006,,,,,,,,,,,,,,,,,,,,
1607872731.469,,2.500000e+001,1.159922e+002,1.156892e+002,2,0,2.064516e+000,0.000000e+000,3.665828e+000,3.628214e+000,5.210701e-001,4.708714e-001,3.729746e+000,6.226023e-001,5.724037e-001,9.275667e-006,9.295392e-006,,,,,,,,,,,,,,,,,,,,
1607872761.029,,2.500000e+001,1.147781e+002,1.144464e+002,2,0,1.032258e+000,0.000000e+000,3.321279e+000,3.271687e+000,-2.910560e-002,-5.171204e-002,3.169468e+000,-1.313242e-001,-1.539307e-001,-1.389984e-006,-1.420362e-006,,,,,,,,,,,,,,,,,,,,
1607872790.399,,2.500000e+001,1.136733e+002,1.134412e+002,2,0,0.000000e+000,0.000000e+000,3.200885e+000,3.159075e+000,-3.664899e-001,-3.664899e-001,3.359580e+000,-1.659851e-001,-1.659851e-001,-7.750306e-006,-7.708972e-006,,,,,,,,,,,,,,,,,,,,
1607872848.859,,2.500000e+001,1.118181e+002,1.113911e+002,1,0,3.096774e+000,0.000000e+000,3.864652e+000,,,,,,,1.170498e-006,,,,,,,,,,,,,,,,,,,,,
1607872877.669,,2.500000e+001,1.105311e+002,1.101008e+002,1,0,2.064516e+000,0.000000e+000,4.388647e+000,,,,,,,9.110343e-006,,,,,,,,,,,,,,,,,,,,,
1607872906.069,,2.500000e+001,1.093440e+002,1.091229e+002,1,0,1.032258e+000,0.000000e+000,4.042725e+000,,,,,,,-1.203691e-006,,,,,,,,,,,,,,,,,,,,,
1607872934.579,,2.500000e+001,1.080250e+002,1.078064e+002,1,0,0.000000e+000,0.000000e+000,3.881132e+000,,,,,,,-7.673123e-006,,,,,,,,,,,,,,,,,,,,,
1607872934.579,,2.500000e+001,1.074990e+002,1.069659e+002,2,0,3.096774e+000,0.000000e+000,4.386053e+000,4.358816e+000,1.638934e-001,7.665873e-002,4.244535e+000,4.961267e-002,-3.762197e-002,1.210472e-006,1.307446e-006,,,,,,,,,,,,,,,,,,,,
1607872963.739,,2.500000e+001,1.061741e+002,1.056917e+002,2,0,2.064516e+000,0.000000e+000,4.898146e+000,4.869307e+000,5.238470e-001,4.585576e-001,4.975496e+000,6.300367e-001,5.647473e-001,9.347496e-006,9.333868e-006,,,,,,,,,,,,,,,,,,,,
1607872993.409,,2.500000e+001,1.050073e+002,1.045997e+002,2,0,1.032258e+000,0.000000e+000,4.506599e+000,4.469368e+000,-2.967339e-002,-6.005239e-002,4.370190e+000,-1.288512e-001,-1.592302e-001,-1.284861e-006,-1.341905e-006,,,,,,,,,,,,,,,,,,,,
1607873022.539,,2.500000e+001,1.038040e+002,1.035434e+002,2,0,0.000000e+000,0.000000e+000,4.319371e+000,4.294957e+000,-3.677902e-001,-3.677902e-001,4.495543e+000,-1.672044e-001,-1.672044e-001,-7.692404e-006,-7.568196e-006,,,,,,,,,,,,,,,,,,,,
1607873050.369,,2.500000e+001,1.030630e+002,1.027623e+002,1,0,3.096774e+000,0.000000e+000,4.825208e+000,,,,,,,1.346591e-006,,,,,,,,,,,,,,,,,,,,,
1607873079.349,,2.500000e+001,1.019532e+002,1.017032e+002,1,0,2.064516e+000,0.000000e+000,5.353933e+000,,,,,,,9.338037e-006,,,,,,,,,,,,,,,,,,,,,
1607873108.399,,2.500000e+001,1.008398e+002,1.005822e+002,1,0,1.032258e+000,0.000000e+000,4.981918e+000,,,,,,,-1.326218e-006,,,,,,,,,,,,,,,,,,,,,
1607873137.739,,2.500000e+001,9.951408e+001,9.927274e+001,1,0,0.000000e+000,0.000000e+000,4.820020e+000,,,,,,,-7.605253e-006,,,,,,,,,,,,,,,,,,,,,
1607873137.739,,2.500000e+001,9.904260e+001,9.871034e+001,2,0,3.096774e+000,0.000000e+000,5.312428e+000,5.284429e+000,1.573899e-001,6.381464e-002,5.177066e+000,5.002760e-002,-4.354763e-002,1.041612e-006,1.143286e-006,,,,,,,,,,,,,,,,,,,,
1607873166.999,,2.500000e+001,9.766621e+001,9.732458e+001,2,0,2.064516e+000,0.000000e+000,5.855344e+000,5.822614e+000,5.138597e-001,4.553761e-001,5.936489e+000,6.277346e-001,5.692511e-001,9.026073e-006,9.140007e-006,,,,,,,,,,,,,,,,,,,,
1607873196.509,,2.500000e+001,9.653915e+001,9.618541e+001,2,0,1.032258e+000,0.000000e+000,5.494164e+000,5.458610e+000,-2.882978e-002,-5.948639e-002,5.355720e+000,-1.317203e-001,-1.623769e-001,-1.365945e-006,-1.330001e-006,,,,,,,,,,,,,,,,,,,,
1607873259.390,,2.500000e+001,9.370391e+001,9.345650e+001,2,0,0.000000e+000,0.000000e+000,5.516747e+000,5.469368e+000,-3.708906e-001,-3.708906e-001,5.669796e+000,-1.704621e-001,-1.704621e-001,-7.526658e-006,-7.694165e-006,,,,,,,,,,,,,,,,,,,,
1607873287.860,,2.500000e+001,9.297065e+001,9.260250e+001,1,0,3.096774e+000,0.000000e+000,5.989624e+000,,,,,,,1.006003e-006,,,,,,,,,,,,,,,,,,,,,
1607873317.490,,2.500000e+001,9.176608e+001,9.150850e+001,1,0,2.064516e+000,0.000000e+000,6.522316e+000,,,,,,,9.215437e-006,,,,,,,,,,,,,,,,,,,,,
1607873346.610,,2.500000e+001,9.046181e+001,9.019196e+001,1,0,1.032258e+000,0.000000e+000,6.164492e+000,,,,,,,-1.198292e-006,,,,,,,,,,,,,,,,,,,,,
1607873375.860,,2.500000e+001,8.938094e+001,8.874921e+001,1,0,0.000000e+000,0.000000e+000,5.995728e+000,,,,,,,-7.438735e-006,,,,,,,,,,,,,,,,,,,,,
1607873375.860,,2.500000e+001,8.874921e+001,8.822471e+001,2,0,3.096774e+000,0.000000e+000,6.477455e+000,6.441367e+000,1.482521e-001,5.211544e-002,6.340786e+000,4.767092e-002,-4.846573e-002,9.982905e-007,9.427022e-007,,,,,,,,,,,,,,,,,,,,
1607873405.300,,2.500000e+001,8.726245e+001,8.684282e+001,2,0,2.064516e+000,0.000000e+000,7.069352e+000,7.036011e+000,5.167572e-001,4.542036e-001,7.152367e+000,6.331131e-001,5.705595e-001,9.142328e-006,9.187177e-006,,,,,,,,,,,,,,,,,,,,
1607873461.240,,2.500000e+001,8.476920e+001,8.419051e+001,2,0,1.032258e+000,0.000000e+000,6.843671e+000,6.815824e+000,-2.203859e-002,-5.241728e-002,6.710443e+000,-1.274187e-001,-1.577973e-001,-1.344335e-006,-1.201959e-006,,,,,,,,,,,,,,,,,,,,
1607873489.290,,2.500000e+001,8.355169e+001,8.306166e+001,2,0,0.000000e+000,0.000000e+000,6.708171e+000,6.659038e+000,-3.695121e-001,-3.695121e-001,6.856874e+000,-1.716752e-001,-1.716752e-001,-7.422961e-006,-7.632436e-006,,,,,,,,,,,,,,,,,,,,
1607873517.890,,2.500000e+001,8.279949e+001,8.229996e+001,1,0,3.096774e+000,0.000000e+000,7.184100e+000,,,,,,,9.434880e-007,,,,,,,,,,,,,,,,,,,,,
1607873547.620,,2.500000e+001,8.148022e+001,8.116737e+001,1,0,2.064516e+000,0.000000e+000,7.692225e+000,,,,,,,8.807372e-006,,,,,,,,,,,,,,,,,,,,,
1607873576.790,,2.500000e+001,8.023058e+001,7.989323e+001,1,0,1.032258e+000,0.000000e+000,7.313191e+000,,,,,,,-1.515407e-006,,,,,,,,,,,,,,,,,,,,,
1607873605.990,,2.500000e+001,7.889629e+001,7.853685e+001,1,0,0.000000e+000,0.000000e+000,7.171893e+000,,,,,,,-7.565395e-006,,,,,,,,,,,,,,,,,,,,,
1607873605.990,,2.500000e+001,7.817508e+001,7.774798e+001,2,0,3.096774e+000,0.000000e+000,7.671320e+000,7.626764e+000,1.397989e-001,4.262161e-002,7.534055e+000,4.708985e-002,-5.008745e-002,7.726194e-007,7.570343e-007,,,,,,,,,,,,,,,,,,,,
1607873657.170,,2.500000e+001,7.579250e+001,7.534919e+001,2,0,2.064516e+000,0.000000e+000,8.344244e+000,8.319525e+000,5.310264e-001,4.638634e-001,8.429419e+000,6.409202e-001,5.737572e-001,9.461917e-006,9.477822e-006,,,,,,,,,,,,,,,,,,,,
1607873685.120,,2.500000e+001,7.446445e+001,7.419862e+001,2,0,1.032258e+000,0.000000e+000,7.931182e+000,7.901503e+000,-2.956240e-002,-6.173277e-002,7.805429e+000,-1.256360e-001,-1.578064e-001,-1.432403e-006,-1.342371e-006,,,,,,,,,,,,,,,,,,,,
1607873714.230,,2.500000e+001,7.321579e+001,7.299773e+001,2,0,0.000000e+000,0.000000e+000,7.783932e+000,7.743954e+000,-3.767967e-001,-3.767967e-001,7.945992e+000,-1.747589e-001,-1.747589e-001,-7.635361e-006,-7.717928e-006,,,,,,,,,,,,,,,,,,,,
1607873743.430,,2.500000e+001,7.259985e+001,7.216695e+001,1,0,3.096774e+000,0.000000e+000,8.260929e+000,,,,,,,8.239876e-007,,,,,,,,,,,,,,,,,,,,,
1607873772.350,,2.500000e+001,7.132404e+001,7.090926e+001,1,0,2.064516e+000,0.000000e+000,8.789960e+000,,,,,,,9.324896e-006,,,,,,,,,,,,,,,,,,,,,
1607873800.940,,2.500000e+001,6.999072e+001,6.951701e+001,1,0,1.032258e+000,0.000000e+000,8.425727e+000,,,,,,,-1.008913e-006,,,,,,,,,,,,,,,,,,,,,
1607873851.930,,2.500000e+001,6.852420e+001,6.701657e+001,1,0,0.000000e+000,0.000000e+000,8.320745e+000,,,,,,,-7.941533e-006,,,,,,,,,,,,,,,,,,,,,
1607873851.930,,2.500000e+001,6.692061e+001,6.643269e+001,2,0,3.096774e+000,0.000000e+000,8.794385e+000,8.769131e+000,1.400371e-001,3.205013e-002,8.669095e+000,4.000147e-002,-6.798553e-002,6.671762e-007,6.969640e-007,,,,,,,,,,,,,,,,,,,,
1607873880.640,,2.500000e+001,6.560101e+001,6.522746e+001,2,0,2.064516e+000,0.000000e+000,9.364614e+000,9.330587e+000,5.395185e-001,4.679832e-001,9.441393e+000,6.503240e-001,5.787888e-001,9.628857e-006,9.629497e-006,,,,,,,,,,,,,,,,,,,,
1607873909.750,,2.500000e+001,6.422033e+001,6.372729e+001,2,0,1.032258e+000,0.000000e+000,8.960402e+000,8.935225e+000,-3.163415e-002,-6.814194e-002,8.826333e+000,-1.405266e-001,-1.770344e-001,-1.270208e-006,-1.360662e-006,,,,,,,,,,,,,,,,,,,,
1607873939.460,,2.500000e+001,6.281310e+001,6.223598e+001,2,0,0.000000e+000,0.000000e+000,8.759899e+000,8.731823e+000,-3.798237e-001,-3.798237e-001,8.933674e+000,-1.779728e-001,-1.779728e-001,-7.805938e-006,-7.755676e-006,,,,,,,,,,,,,,,,,,,,
1607873968.951,,2.500000e+001,6.211718e+001,6.147443e+001,1,0,3.096774e+000,0.000000e+000,9.238422e+000,,,,,,,6.994524e-007,,,,,,,,,,,,,,,,,,,,,
1607873997.721,,2.500000e+001,6.072208e+001,6.025655e+001,1,0,2.064516e+000,0.000000e+000,9.804379e+000,,,,,,,9.529816e-006,,,,,,,,,,,,,,,,,,,,,
1607874070.201,,2.500000e+001,5.728497e+001,5.660154e+001,1,0,1.032258e+000,0.000000e+000,1.929808e+000,,,,,,,-1.202105e-006,,,,,,,,,,,,,,,,,,,,,
1607874099.901,,2.500000e+001,5.574949e+001,5.504057e+001,1,0,0.000000e+000,0.000000e+000,1.890288e+000,,,,,,,-7.886352e-006,,,,,,,,,,,,,,,,,,,,,
1607874099.901,,2.500000e+001,5.504057e+001,5.437731e+001,2,0,3.096774e+000,0.000000e+000,1.986877e+000,1.980240e+000,2.932928e-002,4.910827e-003,1.959755e+000,8.844475e-003,-1.557398e-002,7.628114e-007,7.326016e-007,,,,,,,,,,,,,,,,,,,,
1607874129.261,,2.500000e+001,5.339956e+001,5.291661e+001,2,0,2.064516e+000,0.000000e+000,2.106661e+000,2.099031e+000,1.093021e-001,9.437060e-002,2.123569e+000,1.338399e-001,1.189084e-001,9.934651e-006,9.693773e-006,,,,,,,,,,,,,,,,,,,,
1607874158.531,,2.500000e+001,5.188292e+001,5.137837e+001,2,0,1.032258e+000,0.000000e+000,2.026246e+000,2.019455e+000,-4.016832e-003,-1.222730e-002,1.997477e+000,-2.599497e-002,-3.420544e-002,-1.042994e-006,-1.071458e-006,,,,,,,,,,,,,,,,,,,,
1607874187.791,,2.500000e+001,5.048296e+001,4.984575e+001,2,0,0.000000e+000,0.000000e+000,1.983673e+000,1.977722e+000,-7.953274e-002,-7.953274e-002,2.021077e+000,-3.617764e-002,-3.617764e-002,-7.918803e-006,-7.951487e-006,,,,,,,,,,,,,,,,,,,,
1607874216.941,,2.500000e+001,4.960118e+001,4.902701e+001,1,0,3.096774e+000,0.000000e+000,2.079042e+000,,,,,,,6.762857e-007,,,,,,,,,,,,,,,,,,,,,
1607874260.681,,2.500000e+001,4.731352e+001,4.664413e+001,1,0,2.064516e+000,0.000000e+000,-2.023194e+000,,,,,,,9.616633e-006,,,,,,,,,,,,,,,,,,,,,
1607874290.201,,2.500000e+001,4.585416e+001,4.526220e+001,1,0,1.032258e+000,0.000000e+000,-2.211490e+000,,,,,,,-8.789211e-007,,,,,,,,,,,,,,,,,,,,,
1607874319.551,,2.500000e+001,4.439867e+001,4.385237e+001,1,0,0.000000e+000,0.000000e+000,-2.328069e+000,,,,,,,-7.895622e-006,,,,,,,,,,,,,,,,,,,,,
1607874319.551,,2.500000e+001,4.372811e+001,4.309149e+001,2,0,3.096774e+000,0.000000e+000,-2.097963e+000,-2.109941e+000,7.310820e-002,6.446362e-003,-2.159456e+000,2.359343e-002,-4.306841e-002,5.783804e-007,6.420232e-007,,,,,,,,,,,,,,,,,,,,
1607874348.721,,2.500000e+001,4.240861e+001,4.177131e+001,2,0,2.064516e+000,0.000000e+000,-1.810330e+000,-1.826429e+000,2.757856e-001,2.321162e-001,-1.770600e+000,3.316144e-001,2.879450e-001,9.878670e-006,9.832373e-006,,,,,,,,,,,,,,,,,,,,
1607874378.431,,2.500000e+001,4.102781e+001,4.042174e+001,2,0,1.032258e+000,0.000000e+000,-2.019074e+000,-2.032197e+000,-1.347121e-002,-3.445196e-002,-2.087457e+000,-6.873211e-002,-8.971286e-002,-1.280961e-006,-1.200489e-006,,,,,,,,,,,,,,,,,,,,
1607874677.992,,2.500000e+001,4.000013e+001,4.000331e+001,2,0,0.000000e+000,0.000000e+000,5.171435e+000,1.509575e+000,-1.939646e-001,-1.939646e-001,1.617511e+000,-8.602810e-002,-8.602810e-002,-8.131668e-006,-8.042458e-006,,,,,,,,,,,,,,,,,,,,
1607874706.212,,2.500000e+001,3.998187e+001,4.001046e+001,1,0,3.096774e+000,0.000000e+000,5.437095e+000,,,,,,,1.037028e-006,,,,,,,,,,,,,,,,,,,,,
1607874734.422,,2.500000e+001,3.999060e+001,3.998902e+001,1,0,2.064516e+000,0.000000e+000,-1.991302e+000,,,,,,,9.901109e-006,,,,,,,,,,,,,,,,,,,,,
1607874978.512,,2.500000e+001,3.796412e+001,3.798726e+001,1,0,1.032258e+000,0.000000e+000,4.462043e+000,,,,,,,-1.846201e-006,,,,,,,,,,,,,,,,,,,,,
1607875061.492,,2.500000e+001,3.723885e+001,3.697757e+001,1,0,0.000000e+000,0.000000e+000,4.763561e+000,,,,,,,-8.165895e-006,,,,,,,,,,,,,,,,,,,,,
1607875061.492,,2.500000e+001,3.696895e+001,3.678024e+001,2,0,3.096774e+000,0.000000e+000,5.059434e+000,5.029068e+000,8.092832e-002,3.885651e-002,4.978579e+000,3.043842e-002,-1.163340e-002,1.153618e-006,1.174383e-006,,,,,,,,,,,,,,,,,,,,
1607875111.202,,2.500000e+001,3.621587e+001,3.599933e+001,2,0,2.064516e+000,0.000000e+000,5.459068e+000,5.432059e+000,2.711900e-001,2.400250e-001,5.490539e+000,3.296694e-001,2.985044e-001,9.709911e-006,9.636060e-006,,,,,,,,,,,,,,,,,,,,
1607875156.712,,2.500000e+001,3.546705e+001,3.523139e+001,2,0,1.032258e+000,0.000000e+000,-2.214237e+000,1.540093e+000,-1.825233e-002,-3.585887e-002,1.483537e+000,-7.480796e-002,-9.241450e-002,-1.562017e-006,-1.472996e-006,,,,,,,,,,,,,,,,,,,,
1607875203.782,,2.500000e+001,3.465878e+001,3.443703e+001,2,0,0.000000e+000,0.000000e+000,-2.225376e+000,-2.247272e+000,-1.954062e-001,-1.954062e-001,-2.138189e+000,-8.632231e-002,-8.632231e-002,-7.924173e-006,-7.932074e-006,,,,,,,,,,,,,,,,,,,,
1607875243.642,,2.500000e+001,3.424636e+001,3.398311e+001,1,0,3.096774e+000,0.000000e+000,-1.938201e+000,,,,,,,1.019478e-006,,,,,,,,,,,,,,,,,,,,,
1607875286.972,,2.500000e+001,3.348592e+001,3.318864e+001,1,0,2.064516e+000,0.000000e+000,-1.626459e+000,,,,,,,9.614989e-006,,,,,,,,,,,,,,,,,,,,,
1607875327.022,,2.500000e+001,3.273124e+001,3.245803e+001,1,0,1.032258e+000,0.000000e+000,-1.806973e+000,,,,,,,-1.318622e-006,,,,,,,,,,,,,,,,,,,,,
1607875367.632,,2.500000e+001,3.198883e+001,3.171199e+001,1,0,0.000000e+000,0.000000e+000,-1.887694e+000,,,,,,,-7.917712e-006,,,,,,,,,,,,,,,,,,,,,
1607875367.632,,2.500000e+001,3.169491e+001,3.145490e+001,2,0,3.096774e+000,0.000000e+000,-1.635615e+000,-1.647211e+000,8.993055e-002,2.788508e-002,-1.698592e+000,3.855015e-002,-2.349532e-002,1.193053e-006,1.292501e-006,,,,,,,,,,,,,,,,,,,,
1607875407.723,,2.500000e+001,3.094655e+001,3.071144e+001,2,0,2.064516e+000,0.000000e+000,-1.354238e+000,-1.369726e+000,2.688001e-001,2.269135e-001,-1.311920e+000,3.266064e-001,2.847197e-001,9.594296e-006,9.521267e-006,,,,,,,,,,,,,,,,,,,,
1607875449.963,,2.500000e+001,3.019136e+001,2.994741e+001,2,0,1.032258e+000,0.000000e+000,-1.561456e+000,-1.574884e+000,-2.073535e-002,-4.156196e-002,-1.632001e+000,-7.785246e-002,-9.867907e-002,-1.534980e-006,-1.485721e-006,,,,,,,,,,,,,,,,,,,,
1607875489.673,,2.500000e+001,2.946023e+001,2.922763e+001,2,0,0.000000e+000,0.000000e+000,-1.645686e+000,-1.657740e+000,-1.948291e-001,-1.948291e-001,-1.547515e+000,-8.460379e-002,-8.460379e-002,-7.657989e-006,-7.670023e-006,,,,,,,,,,,,,,,,,,,,
1607875531.283,,2.500000e+001,2.898148e+001,2.872027e+001,1,0,3.096774e+000,0.000000e+000,-1.379416e+000,,,,,,,1.305074e-006,,,,,,,,,,,,,,,,,,,,,
1607875573.003,,2.500000e+001,2.821562e+001,2.797183e+001,1,0,2.064516e+000,0.000000e+000,-1.123674e+000,,,,,,,9.552539e-006,,,,,,,,,,,,,,,,,,,,,
1607875614.903,,2.500000e+001,2.746886e+001,2.721337e+001,1,0,1.032258e+000,0.000000e+000,-1.331044e+000,,,,,,,-1.555680e-006,,,,,,,,,,,,,,,,,,,,,
1607875655.273,,2.500000e+001,2.674009e+001,2.649633e+001,1,0,0.000000e+000,0.000000e+000,-1.405509e+000,,,,,,,-7.648763e-006,,,,,,,,,,,,,,,,,,,,,
1607875655.273,,2.500000e+001,2.646295e+001,2.624922e+001,2,0,3.096774e+000,0.000000e+000,-1.166094e+000,-1.175326e+000,9.274385e-002,2.508116e-002,-1.224924e+000,4.314623e-002,-2.451646e-002,1.285531e-006,1.323420e-006,,,,,,,,,,,,,,,,,,,,
1607875699.483,,2.500000e+001,2.572117e+001,2.550304e+001,2,0,2.064516e+000,0.000000e+000,-9.137102e-001,-9.131762e-001,2.668198e-001,2.155492e-001,-8.558500e-001,3.241460e-001,2.728754e-001,9.206808e-006,9.423115e-006,,,,,,,,,,,,,,,,,,,,
1607875743.253,,2.500000e+001,2.496826e+001,2.468995e+001,2,0,1.032258e+000,0.000000e+000,-1.121996e+000,-1.120699e+000,-2.888889e-002,-5.413234e-002,-1.174982e+000,-8.317239e-002,-1.084158e-001,-1.759181e-006,-1.686240e-006,,,,,,,,,,,,,,,,,,,,
1607875778.953,,2.500000e+001,2.423813e+001,2.411040e+001,2,0,0.000000e+000,0.000000e+000,-1.219043e+000,-1.220951e+000,-1.967967e-001,-1.967967e-001,-1.107737e+000,-8.358312e-002,-8.358312e-002,-7.644288e-006,-7.524708e-006,,,,,,,,,,,,,,,,,,,,
1607875831.523,,2.500000e+001,2.374536e+001,2.351548e+001,1,0,3.096774e+000,0.000000e+000,-9.436179e-001,,,,,,,1.294800e-006,,,,,,,,,,,,,,,,,,,,,
1607875876.433,,2.500000e+001,2.299139e+001,2.276704e+001,1,0,2.064516e+000,0.000000e+000,-6.739911e-001,,,,,,,9.674870e-006,,,,,,,,,,,,,,,,,,,,,
1607875921.093,,2.500000e+001,2.223559e+001,2.200011e+001,1,0,1.032258e+000,0.000000e+000,-8.917373e-001,,,,,,,-1.504886e-006,,,,,,,,,,,,,,,,,,,,,
1607875964.523,,2.500000e+001,2.148073e+001,2.124376e+001,1,0,0.000000e+000,0.000000e+000,-9.750515e-001,,,,,,,-7.501767e-006,,,,,,,,,,,,,,,,,,,,,
1607875964.523,,2.500000e+001,2.122211e+001,2.099423e+001,2,0,3.096774e+000,0.000000e+000,-7.408255e-001,-7.501335e-001,9.497929e-002,2.212590e-002,-7.981263e-001,4.698647e-002,-2.586693e-002,1.372158e-006,1.347438e-006,,,,,,,,,,,,,,,,,,,,
1607876007.753,,2.500000e+001,2.048429e+001,2.025518e+001,2,0,2.064516e+000,0.000000e+000,-4.945449e-001,-4.997330e-001,2.688415e-001,2.194422e-001,-4.426173e-001,3.259571e-001,2.765578e-001,9.336705e-006,9.489144e-006,,,,,,,,,,,,,,,,,,,,
1607876051.483,,2.500000e+001,1.973769e+001,1.950881e+001,2,0,1.032258e+000,0.000000e+000,-7.067979e-001,-7.191577e-001,-2.434132e-002,-4.784870e-002,-7.767430e-001,-8.192661e-002,-1.054340e-001,-1.464417e-006,-1.557661e-006,,,,,,,,,,,,,,,,,,,,
1607876109.754,,2.500000e+001,1.873970e+001,1.854200e+001,2,0,0.000000e+000,0.000000e+000,-1.558099e+000,-1.573129e+000,-3.967249e-001,-3.967249e-001,-1.343510e+000,-1.671057e-001,-1.671057e-001,-7.834969e-006,-7.745923e-006,,,,,,,,,,,,,,,,,,,,
1607876139.894,,2.500000e+001,1.849382e+001,1.825653e+001,1,0,3.096774e+000,0.000000e+000,-1.057450e+000,,,,,,,1.462653e-006,,,,,,,,,,,,,,,,,,,,,
1607876184.014,,2.500000e+001,1.773940e+001,1.752534e+001,1,0,2.064516e+000,0.000000e+000,-5.601587e-001,,,,,,,9.400035e-006,,,,,,,,,,,,,,,,,,,,,
1607876230.504,,2.500000e+001,1.699347e+001,1.677417e+001,1,0,1.032258e+000,0.000000e+000,-9.666590e-001,,,,,,,-1.716027e-006,,,,,,,,,,,,,,,,,,,,,
1607876276.644,,2.500000e+001,1.624054e+001,1.602680e+001,1,0,0.000000e+000,0.000000e+000,-1.125811e+000,,,,,,,-7.691082e-006,,,,,,,,,,,,,,,,,,,,,
1607876276.644,,2.500000e+001,1.600795e+001,1.580678e+001,2,0,3.096774e+000,0.000000e+000,-6.527810e-001,-6.690318e-001,1.904164e-001,4.027754e-002,-7.650316e-001,9.441656e-002,-5.572230e-002,1.277087e-006,1.328826e-006,,,,,,,,,,,,,,,,,,,,
1607876323.934,,2.500000e+001,1.524886e+001,1.505109e+001,2,0,2.064516e+000,0.000000e+000,-1.203937e-001,-1.407645e-001,5.389148e-001,4.359330e-001,-3.418069e-002,6.454986e-001,5.425168e-001,9.547455e-006,9.518356e-006,,,,,,,,,,,,,,,,,,,,
1607876370.794,,2.500000e+001,1.449189e+001,1.427814e+001,2,0,1.032258e+000,0.000000e+000,-5.282673e-001,-5.497825e-001,-4.608168e-002,-9.958628e-002,-6.711458e-001,-1.674450e-001,-2.209496e-001,-1.305356e-006,-1.416110e-006,,,,,,,,,,,,,,,,,,,,
1607876416.684,,2.500000e+001,1.371917e+001,1.352388e+001,2,0,0.000000e+000,0.000000e+000,-7.476920e-001,-7.691309e-001,-4.018831e-001,-4.018831e-001,-5.327758e-001,-1.655280e-001,-1.655280e-001,-7.632455e-006,-7.679966e-006,,,,,,,,,,,,,,,,,,,,
1607876465.234,,2.500000e+001,1.322978e+001,1.300844e+001,1,0,3.096774e+000,0.000000e+000,-2.360571e-001,,,,,,,1.175467e-006,,,,,,,,,,,,,,,,,,,,,
1607876509.044,,2.500000e+001,1.246974e+001,1.224447e+001,1,0,2.064516e+000,0.000000e+000,2.876326e-001,,,,,,,9.225454e-006,,,,,,,,,,,,,,,,,,,,,
1607876552.684,,2.500000e+001,1.174338e+001,1.149164e+001,1,0,1.032258e+000,0.000000e+000,-9.155414e-002,,,,,,,-1.064035e-006,,,,,,,,,,,,,,,,,,,,,
1607876596.664,,2.500000e+001,1.099387e+001,1.075920e+001,1,0,0.000000e+000,0.000000e+000,-8.763256e-001,,,,,,,-7.813342e-006,,,,,,,,,,,,,,,,,,,,,
1607876596.664,,2.500000e+001,1.071813e+001,1.049896e+001,2,0,3.096774e+000,0.000000e+000,-5.426108e-001,-5.391775e-001,1.364077e-001,-8.201003e-002,-6.328343e-001,4.275103e-002,-1.756667e-001,5.476977e-009,-7.030394e-010,,,,,,,,,,,,,,,,,,,,
1607876640.934,,2.500000e+001,9.959978e+000,9.764221e+000,2,0,2.064516e+000,0.000000e+000,2.008087e-001,1.525139e-001,5.800347e-001,4.559733e-001,2.989784e-001,7.264991e-001,6.024377e-001,1.042013e-005,1.036083e-005,,,,,,,,,,,,,,,,,,,,
1607876686.224,,2.500000e+001,9.236342e+000,9.036640e+000,2,0,1.032258e+000,0.000000e+000,8.712902e-002,3.799497e-002,1.354213e-001,6.779204e-002,-9.081443e-002,6.611865e-003,-6.101735e-002,2.076283e-006,2.058739e-006,,,,,,,,,,,,,,,,,,,,
1607876732.514,,2.500000e+001,8.489976e+000,8.291843e+000,2,0,0.000000e+000,0.000000e+000,-4.017701e-001,-4.215305e-001,-6.129243e-001,-6.129243e-001,-1.106791e-001,-3.020730e-001,-3.020730e-001,-1.272114e-005,-1.251230e-005,,,,,,,,,,,,,,,,,,,,
1607876778.124,,2.500000e+001,7.982131e+000,7.771080e+000,1,0,3.096774e+000,0.000000e+000,7.568475e-002,,,,,,,-3.688772e-006,,,,,,,,,,,,,,,,,,,,,
1607876823.945,,2.500000e+001,7.238635e+000,7.071600e+000,1,0,2.064516e+000,0.000000e+000,1.013504e+000,,,,,,,1.196905e-005,,,,,,,,,,,,,,,,,,,,,
1607876893.535,,2.500000e+001,6.494895e+000,6.240692e+000,1,0,1.032258e+000,0.000000e+000,9.279012e-001,,,,,,,5.057514e-006,,,,,,,,,,,,,,,,,,,,,
1607876935.645,,2.500000e+001,5.747311e+000,5.534791e+000,1,0,0.000000e+000,0.000000e+000,1.373312e-001,,,,,,,-1.435592e-005,,,,,,,,,,,,,,,,,,,,,
1607876935.645,,2.500000e+001,5.509508e+000,5.296007e+000,2,0,3.096774e+000,0.000000e+000,4.444954e-001,4.418250e-001,-8.482029e-002,-4.388182e-001,2.857927e-001,-2.408526e-001,-5.948505e-001,-5.120131e-006,-5.086145e-006,,,,,,,,,,,,,,,,,,,,
1607876981.005,,2.500000e+001,4.757154e+000,4.560517e+000,2,0,2.064516e+000,0.000000e+000,1.440909e+000,1.439612e+000,6.982277e-001,4.124810e-001,1.593427e+000,8.520419e-001,5.662951e-001,1.218044e-005,1.230011e-005,,,,,,,,,,,,,,,,,,,,
1607877031.045,,2.500000e+001,3.981833e+000,3.760818e+000,2,0,1.032258e+000,0.000000e+000,1.313344e+000,1.297246e+000,3.120317e-001,1.510222e-001,1.144636e+000,1.594216e-001,-1.587868e-003,6.419097e-006,6.339995e-006,,,,,,,,,,,,,,,,,,,,
1607877076.175,,2.500000e+001,3.288397e+000,3.057161e+000,2,0,0.000000e+000,0.000000e+000,5.191119e-001,4.894331e-001,-7.967671e-001,-7.967671e-001,9.374599e-001,-3.487403e-001,-3.487403e-001,-1.291201e-005,-1.335847e-005,,,,,,,,,,,,,,,,,,,,
1607877126.765,,2.500000e+001,2.746999e+000,2.586058e+000,1,0,3.096774e+000,0.000000e+000,5.813687e-001,,,,,,,-7.529019e-006,,,,,,,,,,,,,,,,,,,,,
1607879972.199,,2.500000e+001,1.908498e+000,1.993058e+000,1,0,2.064516e+000,0.000000e+000,4.746777e+000,,,,,,,9.938012e-006,,,,,,,,,,,,,,,,,,,,,
1607879972.199,,2.500000e+001,1.993671e+000,1.997329e+000,2,0,4.000000e+000,0.000000e+000,3.223316e+000,3.208743e+000,-4.237497e-001,-1.567817e+000,3.423416e+000,-2.090766e-001,-1.353144e+000,-1.760710e-005,-1.762294e-005,,,,,,,,,,,,,,,,,,,,